<?xml version="1.0" encoding="UTF-8"?>
<robot generator="Rebot 7.0 (Python 3.8.18 on linux)" generated="2024-05-20T22:24:24.709028" rpa="false" schemaversion="5">
<suite id="s1" name="Tests" source="/home/runner/work/robot-applitools-tests/robot-applitools-tests/tests">
<suite id="s1-s1" name="Visual Test 1" source="/home/runner/work/robot-applitools-tests/robot-applitools-tests/tests/visual_test_1.robot">
<test id="s1-s1-t1" name="Why Applitools Page" line="16">
<kw name="Before Visual Tests" owner="common_keywords" type="SETUP">
<kw name="Open Browser" owner="SeleniumLibrary">
<msg time="2024-05-20T22:24:20.880458" level="INFO">Opening browser 'headless Chrome' to base url 'https://applitools.com/'.</msg>
<arg>${BASE_URL}</arg>
<arg>${HEADLESS} ${BROWSER}</arg>
<doc>Opens a new browser instance to the optional ``url``.</doc>
<status status="PASS" start="2024-05-20T22:24:20.879987" elapsed="3.035531"/>
</kw>
<kw name="Eyes Open" owner="EyesLibrary">
<msg time="2024-05-20T22:24:24.297928" level="ERROR">Re-raising an error received from SDK server: USDKFailure('Request "getAccountInfo" [0--b34fb4bb-5863-42f3-a127-12c00b2c5bea] that was sent to the address "[GET]https://eyesapi.applitools.com/api/sessions/renderinfo?apiKey=%3Capi-key%3E" failed due to unexpected status Unauthorized(401)', '    at Object.afterResponse (/opt/hostedtoolcache/Python/3.8.18/x64/lib/python3.8/site-packages/applitools/core_universal/bin/core/__sea/node_modules/@applitools/core-base/dist/server/req-eyes.js:104:23)\n    at process.processTicksAndRejections (node:internal/process/task_queues:95:5)\n    at async /opt/hostedtoolcache/Python/3.8.18/x64/lib/python3.8/site-packages/applitools/core_universal/bin/core/__sea/node_modules/@applitools/req/dist/index.cjs:9828:20\n    at async req2 (/opt/hostedtoolcache/Python/3.8.18/x64/lib/python3.8/site-packages/applitools/core_universal/bin/core/__sea/node_modules/@applitools/req/dist/index.cjs:9729:18)\n    at async req (/opt/hostedtoolcache/Python/3.8.18/x64/lib/python3.8/site-packages/applitools/core_universal/bin/core/__sea/node_modules/@applitools/req/dist/index.cjs:9640:12)\n    at async getAccountInfo (/opt/hostedtoolcache/Python/3.8.18/x64/lib/python3.8/site-packages/applitools/core_universal/bin/core/__sea/node_modules/@applitools/core-base/dist/server/requests.js:340:26)\n    at async Object.getAccountInfo (/opt/hostedtoolcache/Python/3.8.18/x64/lib/python3.8/site-packages/applitools/core_universal/bin/core/__sea/node_modules/@applitools/core-base/dist/get-account-info.js:34:25)\n    at async Object.openEyes (/opt/hostedtoolcache/Python/3.8.18/x64/lib/python3.8/site-packages/applitools/core_universal/bin/core/__sea/dist/ufg/open-eyes.js:56:25)\n    at async getTypedEyes (/opt/hostedtoolcache/Python/3.8.18/x64/lib/python3.8/site-packages/applitools/core_universal/bin/core/__sea/dist/get-typed-eyes.js:9:20)\n    at async openEyes (/opt/hostedtoolcache/Python/3.8.18/x64/lib/python3.8/site-packages/applitools/core_universal/bin/core/__sea/dist/open-eyes.js:97:22)')</msg>
<msg time="2024-05-20T22:24:24.299024" level="FAIL">EyesLibraryError: Failed to run EyesLibrary
Traceback (most recent call last):
  File "/opt/hostedtoolcache/Python/3.8.18/x64/lib/python3.8/site-packages/EyesLibrary/__init__.py", line 266, in run_keyword
    return DynamicCore.run_keyword(self, name, args, kwargs)
  File "/opt/hostedtoolcache/Python/3.8.18/x64/lib/python3.8/site-packages/robotlibcore.py", line 173, in run_keyword
    return self.keywords[name](*args, **(kwargs or {}))
  File "/opt/hostedtoolcache/Python/3.8.18/x64/lib/python3.8/site-packages/EyesLibrary/keywords/session.py", line 145, in open
    return eyes.open(self.fetch_driver())
  File "/opt/hostedtoolcache/Python/3.8.18/x64/lib/python3.8/site-packages/applitools/common/eyes.py", line 291, in open
    self._open(app_name, test_name, viewport_size, driver)
  File "/opt/hostedtoolcache/Python/3.8.18/x64/lib/python3.8/site-packages/applitools/common/eyes.py", line 220, in _open
    self._eyes_ref = self._commands.manager_open_eyes(
  File "/opt/hostedtoolcache/Python/3.8.18/x64/lib/python3.8/site-packages/applitools/common/command_executor.py", line 156, in manager_open_eyes
    return self._checked_command(context, "EyesManager.openEyes", payload)
  File "/opt/hostedtoolcache/Python/3.8.18/x64/lib/python3.8/site-packages/applitools/common/command_executor.py", line 284, in _checked_command
    _check_error(response_payload)
  File "/opt/hostedtoolcache/Python/3.8.18/x64/lib/python3.8/site-packages/applitools/common/command_executor.py", line 294, in _check_error
    raise usdk_error
applitools.common.errors.USDKFailure: Request "getAccountInfo" [0--b34fb4bb-5863-42f3-a127-12c00b2c5bea] that was sent to the address "[GET]https://eyesapi.applitools.com/api/sessions/renderinfo?apiKey=%3Capi-key%3E" failed due to unexpected status Unauthorized(401)
    at Object.afterResponse (/opt/hostedtoolcache/Python/3.8.18/x64/lib/python3.8/site-packages/applitools/core_universal/bin/core/__sea/node_modules/@applitools/core-base/dist/server/req-eyes.js:104:23)
    at process.processTicksAndRejections (node:internal/process/task_queues:95:5)
    at async /opt/hostedtoolcache/Python/3.8.18/x64/lib/python3.8/site-packages/applitools/core_universal/bin/core/__sea/node_modules/@applitools/req/dist/index.cjs:9828:20
    at async req2 (/opt/hostedtoolcache/Python/3.8.18/x64/lib/python3.8/site-packages/applitools/core_universal/bin/core/__sea/node_modules/@applitools/req/dist/index.cjs:9729:18)
    at async req (/opt/hostedtoolcache/Python/3.8.18/x64/lib/python3.8/site-packages/applitools/core_universal/bin/core/__sea/node_modules/@applitools/req/dist/index.cjs:9640:12)
    at async getAccountInfo (/opt/hostedtoolcache/Python/3.8.18/x64/lib/python3.8/site-packages/applitools/core_universal/bin/core/__sea/node_modules/@applitools/core-base/dist/server/requests.js:340:26)
    at async Object.getAccountInfo (/opt/hostedtoolcache/Python/3.8.18/x64/lib/python3.8/site-packages/applitools/core_universal/bin/core/__sea/node_modules/@applitools/core-base/dist/get-account-info.js:34:25)
    at async Object.openEyes (/opt/hostedtoolcache/Python/3.8.18/x64/lib/python3.8/site-packages/applitools/core_universal/bin/core/__sea/dist/ufg/open-eyes.js:56:25)
    at async getTypedEyes (/opt/hostedtoolcache/Python/3.8.18/x64/lib/python3.8/site-packages/applitools/core_universal/bin/core/__sea/dist/get-typed-eyes.js:9:20)
    at async openEyes (/opt/hostedtoolcache/Python/3.8.18/x64/lib/python3.8/site-packages/applitools/core_universal/bin/core/__sea/dist/open-eyes.js:97:22)
</msg>
<arg>${TEST_NAME}</arg>
<arg>${VIEWPORT_SIZE}</arg>
<arg>${APP_NAME}</arg>
<arg>${HOST_OS}</arg>
<arg>${HOST_APP}</arg>
<arg>${MATCH_LEVEL}</arg>
<arg>${BASELINE_ENV_NAME}</arg>
<arg>${BATCH_NAME}</arg>
<tag>Check flow</tag>
<doc>Shared parameters section from `applitools.yaml` could be overwritten during `Eyes Open` call, see `Preconditions`.</doc>
<status status="FAIL" start="2024-05-20T22:24:23.916363" elapsed="0.382902">EyesLibraryError: Failed to run EyesLibrary
Traceback (most recent call last):
  File "/opt/hostedtoolcache/Python/3.8.18/x64/lib/python3.8/site-packages/EyesLibrary/__init__.py", line 266, in run_keyword
    return DynamicCore.run_keyword(self, name, args, kwargs)
  File "/opt/hostedtoolcache/Python/3.8.18/x64/lib/python3.8/site-packages/robotlibcore.py", line 173, in run_keyword
    return self.keywords[name](*args, **(kwargs or {}))
  File "/opt/hostedtoolcache/Python/3.8.18/x64/lib/python3.8/site-packages/EyesLibrary/keywords/session.py", line 145, in open
    return eyes.open(self.fetch_driver())
  File "/opt/hostedtoolcache/Python/3.8.18/x64/lib/python3.8/site-packages/applitools/common/eyes.py", line 291, in open
    self._open(app_name, test_name, viewport_size, driver)
  File "/opt/hostedtoolcache/Python/3.8.18/x64/lib/python3.8/site-packages/applitools/common/eyes.py", line 220, in _open
    self._eyes_ref = self._commands.manager_open_eyes(
  File "/opt/hostedtoolcache/Python/3.8.18/x64/lib/python3.8/site-packages/applitools/common/command_executor.py", line 156, in manager_open_eyes
    return self._checked_command(context, "EyesManager.openEyes", payload)
    [ Message content over the limit has been removed. ]
    at async req2 (/opt/hostedtoolcache/Python/3.8.18/x64/lib/python3.8/site-packages/applitools/core_universal/bin/core/__sea/node_modules/@applitools/req/dist/index.cjs:9729:18)
    at async req (/opt/hostedtoolcache/Python/3.8.18/x64/lib/python3.8/site-packages/applitools/core_universal/bin/core/__sea/node_modules/@applitools/req/dist/index.cjs:9640:12)
    at async getAccountInfo (/opt/hostedtoolcache/Python/3.8.18/x64/lib/python3.8/site-packages/applitools/core_universal/bin/core/__sea/node_modules/@applitools/core-base/dist/server/requests.js:340:26)
    at async Object.getAccountInfo (/opt/hostedtoolcache/Python/3.8.18/x64/lib/python3.8/site-packages/applitools/core_universal/bin/core/__sea/node_modules/@applitools/core-base/dist/get-account-info.js:34:25)
    at async Object.openEyes (/opt/hostedtoolcache/Python/3.8.18/x64/lib/python3.8/site-packages/applitools/core_universal/bin/core/__sea/dist/ufg/open-eyes.js:56:25)
    at async getTypedEyes (/opt/hostedtoolcache/Python/3.8.18/x64/lib/python3.8/site-packages/applitools/core_universal/bin/core/__sea/dist/get-typed-eyes.js:9:20)
    at async openEyes (/opt/hostedtoolcache/Python/3.8.18/x64/lib/python3.8/site-packages/applitools/core_universal/bin/core/__sea/dist/open-eyes.js:97:22)</status>
</kw>
<status status="FAIL" start="2024-05-20T22:24:20.878786" elapsed="3.421165">EyesLibraryError: Failed to run EyesLibrary
Traceback (most recent call last):
  File "/opt/hostedtoolcache/Python/3.8.18/x64/lib/python3.8/site-packages/EyesLibrary/__init__.py", line 266, in run_keyword
    return DynamicCore.run_keyword(self, name, args, kwargs)
  File "/opt/hostedtoolcache/Python/3.8.18/x64/lib/python3.8/site-packages/robotlibcore.py", line 173, in run_keyword
    return self.keywords[name](*args, **(kwargs or {}))
  File "/opt/hostedtoolcache/Python/3.8.18/x64/lib/python3.8/site-packages/EyesLibrary/keywords/session.py", line 145, in open
    return eyes.open(self.fetch_driver())
  File "/opt/hostedtoolcache/Python/3.8.18/x64/lib/python3.8/site-packages/applitools/common/eyes.py", line 291, in open
    self._open(app_name, test_name, viewport_size, driver)
  File "/opt/hostedtoolcache/Python/3.8.18/x64/lib/python3.8/site-packages/applitools/common/eyes.py", line 220, in _open
    self._eyes_ref = self._commands.manager_open_eyes(
  File "/opt/hostedtoolcache/Python/3.8.18/x64/lib/python3.8/site-packages/applitools/common/command_executor.py", line 156, in manager_open_eyes
    return self._checked_command(context, "EyesManager.openEyes", payload)
    [ Message content over the limit has been removed. ]
    at async req2 (/opt/hostedtoolcache/Python/3.8.18/x64/lib/python3.8/site-packages/applitools/core_universal/bin/core/__sea/node_modules/@applitools/req/dist/index.cjs:9729:18)
    at async req (/opt/hostedtoolcache/Python/3.8.18/x64/lib/python3.8/site-packages/applitools/core_universal/bin/core/__sea/node_modules/@applitools/req/dist/index.cjs:9640:12)
    at async getAccountInfo (/opt/hostedtoolcache/Python/3.8.18/x64/lib/python3.8/site-packages/applitools/core_universal/bin/core/__sea/node_modules/@applitools/core-base/dist/server/requests.js:340:26)
    at async Object.getAccountInfo (/opt/hostedtoolcache/Python/3.8.18/x64/lib/python3.8/site-packages/applitools/core_universal/bin/core/__sea/node_modules/@applitools/core-base/dist/get-account-info.js:34:25)
    at async Object.openEyes (/opt/hostedtoolcache/Python/3.8.18/x64/lib/python3.8/site-packages/applitools/core_universal/bin/core/__sea/dist/ufg/open-eyes.js:56:25)
    at async getTypedEyes (/opt/hostedtoolcache/Python/3.8.18/x64/lib/python3.8/site-packages/applitools/core_universal/bin/core/__sea/dist/get-typed-eyes.js:9:20)
    at async openEyes (/opt/hostedtoolcache/Python/3.8.18/x64/lib/python3.8/site-packages/applitools/core_universal/bin/core/__sea/dist/open-eyes.js:97:22)</status>
</kw>
<kw name="After Visual Tests" owner="common_keywords" type="TEARDOWN">
<kw name="Eyes Close Async" owner="EyesLibrary">
<msg time="2024-05-20T22:24:24.301220" level="FAIL">EyesLibraryError: Failed to run EyesLibrary
Traceback (most recent call last):
  File "/opt/hostedtoolcache/Python/3.8.18/x64/lib/python3.8/site-packages/EyesLibrary/__init__.py", line 266, in run_keyword
    return DynamicCore.run_keyword(self, name, args, kwargs)
  File "/opt/hostedtoolcache/Python/3.8.18/x64/lib/python3.8/site-packages/robotlibcore.py", line 173, in run_keyword
    return self.keywords[name](*args, **(kwargs or {}))
  File "/opt/hostedtoolcache/Python/3.8.18/x64/lib/python3.8/site-packages/EyesLibrary/keywords/session.py", line 164, in close
    return self.current_eyes.close_async()
  File "/opt/hostedtoolcache/Python/3.8.18/x64/lib/python3.8/site-packages/applitools/common/eyes.py", line 391, in close_async
    return self._close(False, False)
  File "/opt/hostedtoolcache/Python/3.8.18/x64/lib/python3.8/site-packages/applitools/common/eyes.py", line 233, in _close
    raise EyesError("Eyes not open")
applitools.common.errors.EyesError: Eyes not open
</msg>
<tag>Check flow</tag>
<doc>Closes a session and returns the results of the session.
If a test is running, aborts it. Otherwise, does nothing.</doc>
<status status="FAIL" start="2024-05-20T22:24:24.300928" elapsed="0.000508">EyesLibraryError: Failed to run EyesLibrary
Traceback (most recent call last):
  File "/opt/hostedtoolcache/Python/3.8.18/x64/lib/python3.8/site-packages/EyesLibrary/__init__.py", line 266, in run_keyword
    return DynamicCore.run_keyword(self, name, args, kwargs)
  File "/opt/hostedtoolcache/Python/3.8.18/x64/lib/python3.8/site-packages/robotlibcore.py", line 173, in run_keyword
    return self.keywords[name](*args, **(kwargs or {}))
  File "/opt/hostedtoolcache/Python/3.8.18/x64/lib/python3.8/site-packages/EyesLibrary/keywords/session.py", line 164, in close
    return self.current_eyes.close_async()
  File "/opt/hostedtoolcache/Python/3.8.18/x64/lib/python3.8/site-packages/applitools/common/eyes.py", line 391, in close_async
    return self._close(False, False)
  File "/opt/hostedtoolcache/Python/3.8.18/x64/lib/python3.8/site-packages/applitools/common/eyes.py", line 233, in _close
    raise EyesError("Eyes not open")
applitools.common.errors.EyesError: Eyes not open
</status>
</kw>
<kw name="Close All Browsers" owner="SeleniumLibrary">
<doc>Closes all open browsers and resets the browser cache.</doc>
<status status="NOT RUN" start="2024-05-20T22:24:24.301632" elapsed="0.000056"/>
</kw>
<status status="FAIL" start="2024-05-20T22:24:24.300446" elapsed="0.001357">EyesLibraryError: Failed to run EyesLibrary
Traceback (most recent call last):
  File "/opt/hostedtoolcache/Python/3.8.18/x64/lib/python3.8/site-packages/EyesLibrary/__init__.py", line 266, in run_keyword
    return DynamicCore.run_keyword(self, name, args, kwargs)
  File "/opt/hostedtoolcache/Python/3.8.18/x64/lib/python3.8/site-packages/robotlibcore.py", line 173, in run_keyword
    return self.keywords[name](*args, **(kwargs or {}))
  File "/opt/hostedtoolcache/Python/3.8.18/x64/lib/python3.8/site-packages/EyesLibrary/keywords/session.py", line 164, in close
    return self.current_eyes.close_async()
  File "/opt/hostedtoolcache/Python/3.8.18/x64/lib/python3.8/site-packages/applitools/common/eyes.py", line 391, in close_async
    return self._close(False, False)
  File "/opt/hostedtoolcache/Python/3.8.18/x64/lib/python3.8/site-packages/applitools/common/eyes.py", line 233, in _close
    raise EyesError("Eyes not open")
applitools.common.errors.EyesError: Eyes not open
</status>
</kw>
<status status="FAIL" start="2024-05-20T22:24:20.877087" elapsed="3.424837">Setup failed:
EyesLibraryError: Failed to run EyesLibrary
Traceback (most recent call last):
  File "/opt/hostedtoolcache/Python/3.8.18/x64/lib/python3.8/site-packages/EyesLibrary/__init__.py", line 266, in run_keyword
    return DynamicCore.run_keyword(self, name, args, kwargs)
  File "/opt/hostedtoolcache/Python/3.8.18/x64/lib/python3.8/site-packages/robotlibcore.py", line 173, in run_keyword
    return self.keywords[name](*args, **(kwargs or {}))
  File "/opt/hostedtoolcache/Python/3.8.18/x64/lib/python3.8/site-packages/EyesLibrary/keywords/session.py", line 145, in open
    return eyes.open(self.fetch_driver())
  File "/opt/hostedtoolcache/Python/3.8.18/x64/lib/python3.8/site-packages/applitools/common/eyes.py", line 291, in open
    self._open(app_name, test_name, viewport_size, driver)
  File "/opt/hostedtoolcache/Python/3.8.18/x64/lib/python3.8/site-packages/applitools/common/eyes.py", line 220, in _open
    self._eyes_ref = self._commands.manager_open_eyes(
  File "/opt/hostedtoolcache/Python/3.8.18/x64/lib/python3.8/site-packages/applitools/common/command_executor.py", line 156, in manager_open_eyes
    return self._checked_command(context, "EyesManager.openEyes", payload)
    [ Message content over the limit has been removed. ]
    at async req2 (/opt/hostedtoolcache/Python/3.8.18/x64/lib/python3.8/site-packages/applitools/core_universal/bin/core/__sea/node_modules/@applitools/req/dist/index.cjs:9729:18)
    at async req (/opt/hostedtoolcache/Python/3.8.18/x64/lib/python3.8/site-packages/applitools/core_universal/bin/core/__sea/node_modules/@applitools/req/dist/index.cjs:9640:12)
    at async getAccountInfo (/opt/hostedtoolcache/Python/3.8.18/x64/lib/python3.8/site-packages/applitools/core_universal/bin/core/__sea/node_modules/@applitools/core-base/dist/server/requests.js:340:26)
    at async Object.getAccountInfo (/opt/hostedtoolcache/Python/3.8.18/x64/lib/python3.8/site-packages/applitools/core_universal/bin/core/__sea/node_modules/@applitools/core-base/dist/get-account-info.js:34:25)
    at async Object.openEyes (/opt/hostedtoolcache/Python/3.8.18/x64/lib/python3.8/site-packages/applitools/core_universal/bin/core/__sea/dist/ufg/open-eyes.js:56:25)
    at async getTypedEyes (/opt/hostedtoolcache/Python/3.8.18/x64/lib/python3.8/site-packages/applitools/core_universal/bin/core/__sea/dist/get-typed-eyes.js:9:20)
    at async openEyes (/opt/hostedtoolcache/Python/3.8.18/x64/lib/python3.8/site-packages/applitools/core_universal/bin/core/__sea/dist/open-eyes.js:97:22)

Also teardown failed:
EyesLibraryError: Failed to run EyesLibrary
Traceback (most recent call last):
  File "/opt/hostedtoolcache/Python/3.8.18/x64/lib/python3.8/site-packages/EyesLibrary/__init__.py", line 266, in run_keyword
    return DynamicCore.run_keyword(self, name, args, kwargs)
  File "/opt/hostedtoolcache/Python/3.8.18/x64/lib/python3.8/site-packages/robotlibcore.py", line 173, in run_keyword
    return self.keywords[name](*args, **(kwargs or {}))
  File "/opt/hostedtoolcache/Python/3.8.18/x64/lib/python3.8/site-packages/EyesLibrary/keywords/session.py", line 164, in close
    return self.current_eyes.close_async()
  File "/opt/hostedtoolcache/Python/3.8.18/x64/lib/python3.8/site-packages/applitools/common/eyes.py", line 391, in close_async
    return self._close(False, False)
  File "/opt/hostedtoolcache/Python/3.8.18/x64/lib/python3.8/site-packages/applitools/common/eyes.py", line 233, in _close
    raise EyesError("Eyes not open")
applitools.common.errors.EyesError: Eyes not open
</status>
</test>
<test id="s1-s1-t2" name="Eyes Page" line="17">
<tag>robot:exit</tag>
<status status="FAIL" start="2024-05-20T22:24:24.302330" elapsed="0.000420">Test execution stopped due to a fatal error.</status>
</test>
<doc>Test Template at Suite Level</doc>
<meta name="Applitools TestResults Path">/tmp/tmpqh2icfpg/EyesTestResults-e629b945bf4642bf9063cb8e32f81214.json</meta>
<status status="FAIL" start="2024-05-20T22:24:19.374000" elapsed="4.928474"/>
</suite>
<suite id="s1-s2" name="Visual Test 2" source="/home/runner/work/robot-applitools-tests/robot-applitools-tests/tests/visual_test_2.robot">
<test id="s1-s2-t1" name="Autonomoues Page" line="15">
<kw name="Before Visual Tests" owner="common_keywords" type="SETUP">
<kw name="Open Browser" owner="SeleniumLibrary">
<msg time="2024-05-20T22:24:20.879845" level="INFO">Opening browser 'headless Chrome' to base url 'https://applitools.com/'.</msg>
<arg>${BASE_URL}</arg>
<arg>${HEADLESS} ${BROWSER}</arg>
<doc>Opens a new browser instance to the optional ``url``.</doc>
<status status="PASS" start="2024-05-20T22:24:20.879384" elapsed="2.938477"/>
</kw>
<kw name="Eyes Open" owner="EyesLibrary">
<msg time="2024-05-20T22:24:24.297285" level="ERROR">Re-raising an error received from SDK server: USDKFailure('Request "getAccountInfo" [0--cc57a96f-fcd5-4648-8160-4c6084163466] that was sent to the address "[GET]https://eyesapi.applitools.com/api/sessions/renderinfo?apiKey=%3Capi-key%3E" failed due to unexpected status Unauthorized(401)', '    at Object.afterResponse (/opt/hostedtoolcache/Python/3.8.18/x64/lib/python3.8/site-packages/applitools/core_universal/bin/core/__sea/node_modules/@applitools/core-base/dist/server/req-eyes.js:104:23)\n    at process.processTicksAndRejections (node:internal/process/task_queues:95:5)\n    at async /opt/hostedtoolcache/Python/3.8.18/x64/lib/python3.8/site-packages/applitools/core_universal/bin/core/__sea/node_modules/@applitools/req/dist/index.cjs:9828:20\n    at async req2 (/opt/hostedtoolcache/Python/3.8.18/x64/lib/python3.8/site-packages/applitools/core_universal/bin/core/__sea/node_modules/@applitools/req/dist/index.cjs:9729:18)\n    at async req (/opt/hostedtoolcache/Python/3.8.18/x64/lib/python3.8/site-packages/applitools/core_universal/bin/core/__sea/node_modules/@applitools/req/dist/index.cjs:9640:12)\n    at async getAccountInfo (/opt/hostedtoolcache/Python/3.8.18/x64/lib/python3.8/site-packages/applitools/core_universal/bin/core/__sea/node_modules/@applitools/core-base/dist/server/requests.js:340:26)\n    at async Object.getAccountInfo (/opt/hostedtoolcache/Python/3.8.18/x64/lib/python3.8/site-packages/applitools/core_universal/bin/core/__sea/node_modules/@applitools/core-base/dist/get-account-info.js:34:25)\n    at async Object.openEyes (/opt/hostedtoolcache/Python/3.8.18/x64/lib/python3.8/site-packages/applitools/core_universal/bin/core/__sea/dist/ufg/open-eyes.js:56:25)\n    at async getTypedEyes (/opt/hostedtoolcache/Python/3.8.18/x64/lib/python3.8/site-packages/applitools/core_universal/bin/core/__sea/dist/get-typed-eyes.js:9:20)\n    at async openEyes (/opt/hostedtoolcache/Python/3.8.18/x64/lib/python3.8/site-packages/applitools/core_universal/bin/core/__sea/dist/open-eyes.js:97:22)')</msg>
<msg time="2024-05-20T22:24:24.298753" level="FAIL">EyesLibraryError: Failed to run EyesLibrary
Traceback (most recent call last):
  File "/opt/hostedtoolcache/Python/3.8.18/x64/lib/python3.8/site-packages/EyesLibrary/__init__.py", line 266, in run_keyword
    return DynamicCore.run_keyword(self, name, args, kwargs)
  File "/opt/hostedtoolcache/Python/3.8.18/x64/lib/python3.8/site-packages/robotlibcore.py", line 173, in run_keyword
    return self.keywords[name](*args, **(kwargs or {}))
  File "/opt/hostedtoolcache/Python/3.8.18/x64/lib/python3.8/site-packages/EyesLibrary/keywords/session.py", line 145, in open
    return eyes.open(self.fetch_driver())
  File "/opt/hostedtoolcache/Python/3.8.18/x64/lib/python3.8/site-packages/applitools/common/eyes.py", line 291, in open
    self._open(app_name, test_name, viewport_size, driver)
  File "/opt/hostedtoolcache/Python/3.8.18/x64/lib/python3.8/site-packages/applitools/common/eyes.py", line 220, in _open
    self._eyes_ref = self._commands.manager_open_eyes(
  File "/opt/hostedtoolcache/Python/3.8.18/x64/lib/python3.8/site-packages/applitools/common/command_executor.py", line 156, in manager_open_eyes
    return self._checked_command(context, "EyesManager.openEyes", payload)
  File "/opt/hostedtoolcache/Python/3.8.18/x64/lib/python3.8/site-packages/applitools/common/command_executor.py", line 284, in _checked_command
    _check_error(response_payload)
  File "/opt/hostedtoolcache/Python/3.8.18/x64/lib/python3.8/site-packages/applitools/common/command_executor.py", line 294, in _check_error
    raise usdk_error
applitools.common.errors.USDKFailure: Request "getAccountInfo" [0--cc57a96f-fcd5-4648-8160-4c6084163466] that was sent to the address "[GET]https://eyesapi.applitools.com/api/sessions/renderinfo?apiKey=%3Capi-key%3E" failed due to unexpected status Unauthorized(401)
    at Object.afterResponse (/opt/hostedtoolcache/Python/3.8.18/x64/lib/python3.8/site-packages/applitools/core_universal/bin/core/__sea/node_modules/@applitools/core-base/dist/server/req-eyes.js:104:23)
    at process.processTicksAndRejections (node:internal/process/task_queues:95:5)
    at async /opt/hostedtoolcache/Python/3.8.18/x64/lib/python3.8/site-packages/applitools/core_universal/bin/core/__sea/node_modules/@applitools/req/dist/index.cjs:9828:20
    at async req2 (/opt/hostedtoolcache/Python/3.8.18/x64/lib/python3.8/site-packages/applitools/core_universal/bin/core/__sea/node_modules/@applitools/req/dist/index.cjs:9729:18)
    at async req (/opt/hostedtoolcache/Python/3.8.18/x64/lib/python3.8/site-packages/applitools/core_universal/bin/core/__sea/node_modules/@applitools/req/dist/index.cjs:9640:12)
    at async getAccountInfo (/opt/hostedtoolcache/Python/3.8.18/x64/lib/python3.8/site-packages/applitools/core_universal/bin/core/__sea/node_modules/@applitools/core-base/dist/server/requests.js:340:26)
    at async Object.getAccountInfo (/opt/hostedtoolcache/Python/3.8.18/x64/lib/python3.8/site-packages/applitools/core_universal/bin/core/__sea/node_modules/@applitools/core-base/dist/get-account-info.js:34:25)
    at async Object.openEyes (/opt/hostedtoolcache/Python/3.8.18/x64/lib/python3.8/site-packages/applitools/core_universal/bin/core/__sea/dist/ufg/open-eyes.js:56:25)
    at async getTypedEyes (/opt/hostedtoolcache/Python/3.8.18/x64/lib/python3.8/site-packages/applitools/core_universal/bin/core/__sea/dist/get-typed-eyes.js:9:20)
    at async openEyes (/opt/hostedtoolcache/Python/3.8.18/x64/lib/python3.8/site-packages/applitools/core_universal/bin/core/__sea/dist/open-eyes.js:97:22)
</msg>
<arg>${TEST_NAME}</arg>
<arg>${VIEWPORT_SIZE}</arg>
<arg>${APP_NAME}</arg>
<arg>${HOST_OS}</arg>
<arg>${HOST_APP}</arg>
<arg>${MATCH_LEVEL}</arg>
<arg>${BASELINE_ENV_NAME}</arg>
<arg>${BATCH_NAME}</arg>
<tag>Check flow</tag>
<doc>Shared parameters section from `applitools.yaml` could be overwritten during `Eyes Open` call, see `Preconditions`.</doc>
<status status="FAIL" start="2024-05-20T22:24:23.818539" elapsed="0.480458">EyesLibraryError: Failed to run EyesLibrary
Traceback (most recent call last):
  File "/opt/hostedtoolcache/Python/3.8.18/x64/lib/python3.8/site-packages/EyesLibrary/__init__.py", line 266, in run_keyword
    return DynamicCore.run_keyword(self, name, args, kwargs)
  File "/opt/hostedtoolcache/Python/3.8.18/x64/lib/python3.8/site-packages/robotlibcore.py", line 173, in run_keyword
    return self.keywords[name](*args, **(kwargs or {}))
  File "/opt/hostedtoolcache/Python/3.8.18/x64/lib/python3.8/site-packages/EyesLibrary/keywords/session.py", line 145, in open
    return eyes.open(self.fetch_driver())
  File "/opt/hostedtoolcache/Python/3.8.18/x64/lib/python3.8/site-packages/applitools/common/eyes.py", line 291, in open
    self._open(app_name, test_name, viewport_size, driver)
  File "/opt/hostedtoolcache/Python/3.8.18/x64/lib/python3.8/site-packages/applitools/common/eyes.py", line 220, in _open
    self._eyes_ref = self._commands.manager_open_eyes(
  File "/opt/hostedtoolcache/Python/3.8.18/x64/lib/python3.8/site-packages/applitools/common/command_executor.py", line 156, in manager_open_eyes
    return self._checked_command(context, "EyesManager.openEyes", payload)
    [ Message content over the limit has been removed. ]
    at async req2 (/opt/hostedtoolcache/Python/3.8.18/x64/lib/python3.8/site-packages/applitools/core_universal/bin/core/__sea/node_modules/@applitools/req/dist/index.cjs:9729:18)
    at async req (/opt/hostedtoolcache/Python/3.8.18/x64/lib/python3.8/site-packages/applitools/core_universal/bin/core/__sea/node_modules/@applitools/req/dist/index.cjs:9640:12)
    at async getAccountInfo (/opt/hostedtoolcache/Python/3.8.18/x64/lib/python3.8/site-packages/applitools/core_universal/bin/core/__sea/node_modules/@applitools/core-base/dist/server/requests.js:340:26)
    at async Object.getAccountInfo (/opt/hostedtoolcache/Python/3.8.18/x64/lib/python3.8/site-packages/applitools/core_universal/bin/core/__sea/node_modules/@applitools/core-base/dist/get-account-info.js:34:25)
    at async Object.openEyes (/opt/hostedtoolcache/Python/3.8.18/x64/lib/python3.8/site-packages/applitools/core_universal/bin/core/__sea/dist/ufg/open-eyes.js:56:25)
    at async getTypedEyes (/opt/hostedtoolcache/Python/3.8.18/x64/lib/python3.8/site-packages/applitools/core_universal/bin/core/__sea/dist/get-typed-eyes.js:9:20)
    at async openEyes (/opt/hostedtoolcache/Python/3.8.18/x64/lib/python3.8/site-packages/applitools/core_universal/bin/core/__sea/dist/open-eyes.js:97:22)</status>
</kw>
<status status="FAIL" start="2024-05-20T22:24:20.878176" elapsed="3.421529">EyesLibraryError: Failed to run EyesLibrary
Traceback (most recent call last):
  File "/opt/hostedtoolcache/Python/3.8.18/x64/lib/python3.8/site-packages/EyesLibrary/__init__.py", line 266, in run_keyword
    return DynamicCore.run_keyword(self, name, args, kwargs)
  File "/opt/hostedtoolcache/Python/3.8.18/x64/lib/python3.8/site-packages/robotlibcore.py", line 173, in run_keyword
    return self.keywords[name](*args, **(kwargs or {}))
  File "/opt/hostedtoolcache/Python/3.8.18/x64/lib/python3.8/site-packages/EyesLibrary/keywords/session.py", line 145, in open
    return eyes.open(self.fetch_driver())
  File "/opt/hostedtoolcache/Python/3.8.18/x64/lib/python3.8/site-packages/applitools/common/eyes.py", line 291, in open
    self._open(app_name, test_name, viewport_size, driver)
  File "/opt/hostedtoolcache/Python/3.8.18/x64/lib/python3.8/site-packages/applitools/common/eyes.py", line 220, in _open
    self._eyes_ref = self._commands.manager_open_eyes(
  File "/opt/hostedtoolcache/Python/3.8.18/x64/lib/python3.8/site-packages/applitools/common/command_executor.py", line 156, in manager_open_eyes
    return self._checked_command(context, "EyesManager.openEyes", payload)
    [ Message content over the limit has been removed. ]
    at async req2 (/opt/hostedtoolcache/Python/3.8.18/x64/lib/python3.8/site-packages/applitools/core_universal/bin/core/__sea/node_modules/@applitools/req/dist/index.cjs:9729:18)
    at async req (/opt/hostedtoolcache/Python/3.8.18/x64/lib/python3.8/site-packages/applitools/core_universal/bin/core/__sea/node_modules/@applitools/req/dist/index.cjs:9640:12)
    at async getAccountInfo (/opt/hostedtoolcache/Python/3.8.18/x64/lib/python3.8/site-packages/applitools/core_universal/bin/core/__sea/node_modules/@applitools/core-base/dist/server/requests.js:340:26)
    at async Object.getAccountInfo (/opt/hostedtoolcache/Python/3.8.18/x64/lib/python3.8/site-packages/applitools/core_universal/bin/core/__sea/node_modules/@applitools/core-base/dist/get-account-info.js:34:25)
    at async Object.openEyes (/opt/hostedtoolcache/Python/3.8.18/x64/lib/python3.8/site-packages/applitools/core_universal/bin/core/__sea/dist/ufg/open-eyes.js:56:25)
    at async getTypedEyes (/opt/hostedtoolcache/Python/3.8.18/x64/lib/python3.8/site-packages/applitools/core_universal/bin/core/__sea/dist/get-typed-eyes.js:9:20)
    at async openEyes (/opt/hostedtoolcache/Python/3.8.18/x64/lib/python3.8/site-packages/applitools/core_universal/bin/core/__sea/dist/open-eyes.js:97:22)</status>
</kw>
<kw name="After Visual Tests" owner="common_keywords" type="TEARDOWN">
<kw name="Eyes Close Async" owner="EyesLibrary">
<msg time="2024-05-20T22:24:24.300991" level="FAIL">EyesLibraryError: Failed to run EyesLibrary
Traceback (most recent call last):
  File "/opt/hostedtoolcache/Python/3.8.18/x64/lib/python3.8/site-packages/EyesLibrary/__init__.py", line 266, in run_keyword
    return DynamicCore.run_keyword(self, name, args, kwargs)
  File "/opt/hostedtoolcache/Python/3.8.18/x64/lib/python3.8/site-packages/robotlibcore.py", line 173, in run_keyword
    return self.keywords[name](*args, **(kwargs or {}))
  File "/opt/hostedtoolcache/Python/3.8.18/x64/lib/python3.8/site-packages/EyesLibrary/keywords/session.py", line 164, in close
    return self.current_eyes.close_async()
  File "/opt/hostedtoolcache/Python/3.8.18/x64/lib/python3.8/site-packages/applitools/common/eyes.py", line 391, in close_async
    return self._close(False, False)
  File "/opt/hostedtoolcache/Python/3.8.18/x64/lib/python3.8/site-packages/applitools/common/eyes.py", line 233, in _close
    raise EyesError("Eyes not open")
applitools.common.errors.EyesError: Eyes not open
</msg>
<tag>Check flow</tag>
<doc>Closes a session and returns the results of the session.
If a test is running, aborts it. Otherwise, does nothing.</doc>
<status status="FAIL" start="2024-05-20T22:24:24.300693" elapsed="0.000464">EyesLibraryError: Failed to run EyesLibrary
Traceback (most recent call last):
  File "/opt/hostedtoolcache/Python/3.8.18/x64/lib/python3.8/site-packages/EyesLibrary/__init__.py", line 266, in run_keyword
    return DynamicCore.run_keyword(self, name, args, kwargs)
  File "/opt/hostedtoolcache/Python/3.8.18/x64/lib/python3.8/site-packages/robotlibcore.py", line 173, in run_keyword
    return self.keywords[name](*args, **(kwargs or {}))
  File "/opt/hostedtoolcache/Python/3.8.18/x64/lib/python3.8/site-packages/EyesLibrary/keywords/session.py", line 164, in close
    return self.current_eyes.close_async()
  File "/opt/hostedtoolcache/Python/3.8.18/x64/lib/python3.8/site-packages/applitools/common/eyes.py", line 391, in close_async
    return self._close(False, False)
  File "/opt/hostedtoolcache/Python/3.8.18/x64/lib/python3.8/site-packages/applitools/common/eyes.py", line 233, in _close
    raise EyesError("Eyes not open")
applitools.common.errors.EyesError: Eyes not open
</status>
</kw>
<kw name="Close All Browsers" owner="SeleniumLibrary">
<doc>Closes all open browsers and resets the browser cache.</doc>
<status status="NOT RUN" start="2024-05-20T22:24:24.301398" elapsed="0.000058"/>
</kw>
<status status="FAIL" start="2024-05-20T22:24:24.300209" elapsed="0.001367">EyesLibraryError: Failed to run EyesLibrary
Traceback (most recent call last):
  File "/opt/hostedtoolcache/Python/3.8.18/x64/lib/python3.8/site-packages/EyesLibrary/__init__.py", line 266, in run_keyword
    return DynamicCore.run_keyword(self, name, args, kwargs)
  File "/opt/hostedtoolcache/Python/3.8.18/x64/lib/python3.8/site-packages/robotlibcore.py", line 173, in run_keyword
    return self.keywords[name](*args, **(kwargs or {}))
  File "/opt/hostedtoolcache/Python/3.8.18/x64/lib/python3.8/site-packages/EyesLibrary/keywords/session.py", line 164, in close
    return self.current_eyes.close_async()
  File "/opt/hostedtoolcache/Python/3.8.18/x64/lib/python3.8/site-packages/applitools/common/eyes.py", line 391, in close_async
    return self._close(False, False)
  File "/opt/hostedtoolcache/Python/3.8.18/x64/lib/python3.8/site-packages/applitools/common/eyes.py", line 233, in _close
    raise EyesError("Eyes not open")
applitools.common.errors.EyesError: Eyes not open
</status>
</kw>
<status status="FAIL" start="2024-05-20T22:24:20.876892" elapsed="3.424804">Setup failed:
EyesLibraryError: Failed to run EyesLibrary
Traceback (most recent call last):
  File "/opt/hostedtoolcache/Python/3.8.18/x64/lib/python3.8/site-packages/EyesLibrary/__init__.py", line 266, in run_keyword
    return DynamicCore.run_keyword(self, name, args, kwargs)
  File "/opt/hostedtoolcache/Python/3.8.18/x64/lib/python3.8/site-packages/robotlibcore.py", line 173, in run_keyword
    return self.keywords[name](*args, **(kwargs or {}))
  File "/opt/hostedtoolcache/Python/3.8.18/x64/lib/python3.8/site-packages/EyesLibrary/keywords/session.py", line 145, in open
    return eyes.open(self.fetch_driver())
  File "/opt/hostedtoolcache/Python/3.8.18/x64/lib/python3.8/site-packages/applitools/common/eyes.py", line 291, in open
    self._open(app_name, test_name, viewport_size, driver)
  File "/opt/hostedtoolcache/Python/3.8.18/x64/lib/python3.8/site-packages/applitools/common/eyes.py", line 220, in _open
    self._eyes_ref = self._commands.manager_open_eyes(
  File "/opt/hostedtoolcache/Python/3.8.18/x64/lib/python3.8/site-packages/applitools/common/command_executor.py", line 156, in manager_open_eyes
    return self._checked_command(context, "EyesManager.openEyes", payload)
    [ Message content over the limit has been removed. ]
    at async req2 (/opt/hostedtoolcache/Python/3.8.18/x64/lib/python3.8/site-packages/applitools/core_universal/bin/core/__sea/node_modules/@applitools/req/dist/index.cjs:9729:18)
    at async req (/opt/hostedtoolcache/Python/3.8.18/x64/lib/python3.8/site-packages/applitools/core_universal/bin/core/__sea/node_modules/@applitools/req/dist/index.cjs:9640:12)
    at async getAccountInfo (/opt/hostedtoolcache/Python/3.8.18/x64/lib/python3.8/site-packages/applitools/core_universal/bin/core/__sea/node_modules/@applitools/core-base/dist/server/requests.js:340:26)
    at async Object.getAccountInfo (/opt/hostedtoolcache/Python/3.8.18/x64/lib/python3.8/site-packages/applitools/core_universal/bin/core/__sea/node_modules/@applitools/core-base/dist/get-account-info.js:34:25)
    at async Object.openEyes (/opt/hostedtoolcache/Python/3.8.18/x64/lib/python3.8/site-packages/applitools/core_universal/bin/core/__sea/dist/ufg/open-eyes.js:56:25)
    at async getTypedEyes (/opt/hostedtoolcache/Python/3.8.18/x64/lib/python3.8/site-packages/applitools/core_universal/bin/core/__sea/dist/get-typed-eyes.js:9:20)
    at async openEyes (/opt/hostedtoolcache/Python/3.8.18/x64/lib/python3.8/site-packages/applitools/core_universal/bin/core/__sea/dist/open-eyes.js:97:22)

Also teardown failed:
EyesLibraryError: Failed to run EyesLibrary
Traceback (most recent call last):
  File "/opt/hostedtoolcache/Python/3.8.18/x64/lib/python3.8/site-packages/EyesLibrary/__init__.py", line 266, in run_keyword
    return DynamicCore.run_keyword(self, name, args, kwargs)
  File "/opt/hostedtoolcache/Python/3.8.18/x64/lib/python3.8/site-packages/robotlibcore.py", line 173, in run_keyword
    return self.keywords[name](*args, **(kwargs or {}))
  File "/opt/hostedtoolcache/Python/3.8.18/x64/lib/python3.8/site-packages/EyesLibrary/keywords/session.py", line 164, in close
    return self.current_eyes.close_async()
  File "/opt/hostedtoolcache/Python/3.8.18/x64/lib/python3.8/site-packages/applitools/common/eyes.py", line 391, in close_async
    return self._close(False, False)
  File "/opt/hostedtoolcache/Python/3.8.18/x64/lib/python3.8/site-packages/applitools/common/eyes.py", line 233, in _close
    raise EyesError("Eyes not open")
applitools.common.errors.EyesError: Eyes not open
</status>
</test>
<doc>Test Template at Test Case Level</doc>
<meta name="Applitools TestResults Path">/tmp/tmp_ab0zoii/EyesTestResults-c899ce401a364a7abe34de783bb87e24.json</meta>
<status status="FAIL" start="2024-05-20T22:24:19.369124" elapsed="4.933258"/>
</suite>
<doc>[https://pabot.org/?ref=log|Pabot] result from 2 executions.</doc>
<status status="FAIL" start="2024-05-20T22:24:19.348000" elapsed="4.955233"/>
</suite>
<statistics>
<total>
<stat pass="0" fail="3" skip="0">All Tests</stat>
</total>
<tag>
</tag>
<suite>
<stat pass="0" fail="3" skip="0" id="s1" name="Tests">Tests</stat>
<stat pass="0" fail="2" skip="0" id="s1-s1" name="Visual Test 1">Tests.Visual Test 1</stat>
<stat pass="0" fail="1" skip="0" id="s1-s2" name="Visual Test 2">Tests.Visual Test 2</stat>
</suite>
</statistics>
<errors>
<msg time="2024-05-20T22:24:19.755944" level="ERROR">Error in file '/home/runner/work/robot-applitools-tests/robot-applitools-tests/resources/common_keywords.robot' on line 4: Importing library '../resources/common_variables.robot' failed: ModuleNotFoundError: No module named '.'
Traceback (most recent call last):
  None
PYTHONPATH:
  /opt/hostedtoolcache/Python/3.8.18/x64/bin
  /opt/hostedtoolcache/Python/3.8.18/x64/lib/python38.zip
  /opt/hostedtoolcache/Python/3.8.18/x64/lib/python3.8
  /opt/hostedtoolcache/Python/3.8.18/x64/lib/python3.8/lib-dynload
  /opt/hostedtoolcache/Python/3.8.18/x64/lib/python3.8/site-packages</msg>
<msg time="2024-05-20T22:24:24.297928" level="ERROR">Re-raising an error received from SDK server: USDKFailure('Request "getAccountInfo" [0--b34fb4bb-5863-42f3-a127-12c00b2c5bea] that was sent to the address "[GET]https://eyesapi.applitools.com/api/sessions/renderinfo?apiKey=%3Capi-key%3E" failed due to unexpected status Unauthorized(401)', '    at Object.afterResponse (/opt/hostedtoolcache/Python/3.8.18/x64/lib/python3.8/site-packages/applitools/core_universal/bin/core/__sea/node_modules/@applitools/core-base/dist/server/req-eyes.js:104:23)\n    at process.processTicksAndRejections (node:internal/process/task_queues:95:5)\n    at async /opt/hostedtoolcache/Python/3.8.18/x64/lib/python3.8/site-packages/applitools/core_universal/bin/core/__sea/node_modules/@applitools/req/dist/index.cjs:9828:20\n    at async req2 (/opt/hostedtoolcache/Python/3.8.18/x64/lib/python3.8/site-packages/applitools/core_universal/bin/core/__sea/node_modules/@applitools/req/dist/index.cjs:9729:18)\n    at async req (/opt/hostedtoolcache/Python/3.8.18/x64/lib/python3.8/site-packages/applitools/core_universal/bin/core/__sea/node_modules/@applitools/req/dist/index.cjs:9640:12)\n    at async getAccountInfo (/opt/hostedtoolcache/Python/3.8.18/x64/lib/python3.8/site-packages/applitools/core_universal/bin/core/__sea/node_modules/@applitools/core-base/dist/server/requests.js:340:26)\n    at async Object.getAccountInfo (/opt/hostedtoolcache/Python/3.8.18/x64/lib/python3.8/site-packages/applitools/core_universal/bin/core/__sea/node_modules/@applitools/core-base/dist/get-account-info.js:34:25)\n    at async Object.openEyes (/opt/hostedtoolcache/Python/3.8.18/x64/lib/python3.8/site-packages/applitools/core_universal/bin/core/__sea/dist/ufg/open-eyes.js:56:25)\n    at async getTypedEyes (/opt/hostedtoolcache/Python/3.8.18/x64/lib/python3.8/site-packages/applitools/core_universal/bin/core/__sea/dist/get-typed-eyes.js:9:20)\n    at async openEyes (/opt/hostedtoolcache/Python/3.8.18/x64/lib/python3.8/site-packages/applitools/core_universal/bin/core/__sea/dist/open-eyes.js:97:22)')</msg>
<msg time="2024-05-20T22:24:19.755590" level="ERROR">Error in file '/home/runner/work/robot-applitools-tests/robot-applitools-tests/resources/common_keywords.robot' on line 4: Importing library '../resources/common_variables.robot' failed: ModuleNotFoundError: No module named '.'
Traceback (most recent call last):
  None
PYTHONPATH:
  /opt/hostedtoolcache/Python/3.8.18/x64/bin
  /opt/hostedtoolcache/Python/3.8.18/x64/lib/python38.zip
  /opt/hostedtoolcache/Python/3.8.18/x64/lib/python3.8
  /opt/hostedtoolcache/Python/3.8.18/x64/lib/python3.8/lib-dynload
  /opt/hostedtoolcache/Python/3.8.18/x64/lib/python3.8/site-packages</msg>
<msg time="2024-05-20T22:24:24.297285" level="ERROR">Re-raising an error received from SDK server: USDKFailure('Request "getAccountInfo" [0--cc57a96f-fcd5-4648-8160-4c6084163466] that was sent to the address "[GET]https://eyesapi.applitools.com/api/sessions/renderinfo?apiKey=%3Capi-key%3E" failed due to unexpected status Unauthorized(401)', '    at Object.afterResponse (/opt/hostedtoolcache/Python/3.8.18/x64/lib/python3.8/site-packages/applitools/core_universal/bin/core/__sea/node_modules/@applitools/core-base/dist/server/req-eyes.js:104:23)\n    at process.processTicksAndRejections (node:internal/process/task_queues:95:5)\n    at async /opt/hostedtoolcache/Python/3.8.18/x64/lib/python3.8/site-packages/applitools/core_universal/bin/core/__sea/node_modules/@applitools/req/dist/index.cjs:9828:20\n    at async req2 (/opt/hostedtoolcache/Python/3.8.18/x64/lib/python3.8/site-packages/applitools/core_universal/bin/core/__sea/node_modules/@applitools/req/dist/index.cjs:9729:18)\n    at async req (/opt/hostedtoolcache/Python/3.8.18/x64/lib/python3.8/site-packages/applitools/core_universal/bin/core/__sea/node_modules/@applitools/req/dist/index.cjs:9640:12)\n    at async getAccountInfo (/opt/hostedtoolcache/Python/3.8.18/x64/lib/python3.8/site-packages/applitools/core_universal/bin/core/__sea/node_modules/@applitools/core-base/dist/server/requests.js:340:26)\n    at async Object.getAccountInfo (/opt/hostedtoolcache/Python/3.8.18/x64/lib/python3.8/site-packages/applitools/core_universal/bin/core/__sea/node_modules/@applitools/core-base/dist/get-account-info.js:34:25)\n    at async Object.openEyes (/opt/hostedtoolcache/Python/3.8.18/x64/lib/python3.8/site-packages/applitools/core_universal/bin/core/__sea/dist/ufg/open-eyes.js:56:25)\n    at async getTypedEyes (/opt/hostedtoolcache/Python/3.8.18/x64/lib/python3.8/site-packages/applitools/core_universal/bin/core/__sea/dist/get-typed-eyes.js:9:20)\n    at async openEyes (/opt/hostedtoolcache/Python/3.8.18/x64/lib/python3.8/site-packages/applitools/core_universal/bin/core/__sea/dist/open-eyes.js:97:22)')</msg>
</errors>
</robot>
