<?xml version="1.0" encoding="UTF-8"?>
<robot generator="Rebot 7.0 (Python 3.8.18 on linux)" generated="2024-02-29T14:43:01.179004" rpa="false" schemaversion="5">
<suite id="s1" name="Tests" source="/home/runner/work/robot-applitools-tests/robot-applitools-tests/tests">
<suite id="s1-s1" name="Visual Test 1" source="/home/runner/work/robot-applitools-tests/robot-applitools-tests/tests/visual_test_1.robot">
<test id="s1-s1-t1" name="Why Applitools Page" line="10">
<kw name="Before Visual Tests" owner="common_keywords" type="SETUP">
<kw name="Open Browser" owner="SeleniumLibrary">
<msg time="2024-02-29T14:42:48.080245" level="INFO">Opening browser 'headless Chrome' to base url 'https://applitools.com/'.</msg>
<arg>${BASE_URL}</arg>
<arg>${HEADLESS} ${BROWSER}</arg>
<doc>Opens a new browser instance to the optional ``url``.</doc>
<status status="PASS" start="2024-02-29T14:42:48.079803" elapsed="11.700333"/>
</kw>
<kw name="Eyes Open" owner="EyesLibrary">
<msg time="2024-02-29T14:43:00.766754" level="ERROR">Re-raising an error received from SDK server: USDKFailure('Request "getAccountInfo" [0--20edbb2b-5a2f-4b88-b5bb-de5781c2a650] that was sent to the address "[GET]https://eyesapi.applitools.com/api/sessions/renderinfo?apiKey=%3Capi-key%3E" failed due to unexpected status Unauthorized(401)', '    at Object.afterResponse (/opt/hostedtoolcache/Python/3.8.18/x64/lib/python3.8/site-packages/applitools/core_universal/bin/core/__sea/node_modules/@applitools/core-base/dist/server/req-eyes.js:101:23)\n    at /opt/hostedtoolcache/Python/3.8.18/x64/lib/python3.8/site-packages/applitools/core_universal/bin/core/__sea/node_modules/@applitools/req/dist/index.cjs:9828:97\n    at process.processTicksAndRejections (node:internal/process/task_queues:95:5)\n    at async req2 (/opt/hostedtoolcache/Python/3.8.18/x64/lib/python3.8/site-packages/applitools/core_universal/bin/core/__sea/node_modules/@applitools/req/dist/index.cjs:9729:18)\n    at async req (/opt/hostedtoolcache/Python/3.8.18/x64/lib/python3.8/site-packages/applitools/core_universal/bin/core/__sea/node_modules/@applitools/req/dist/index.cjs:9640:12)\n    at async getAccountInfo (/opt/hostedtoolcache/Python/3.8.18/x64/lib/python3.8/site-packages/applitools/core_universal/bin/core/__sea/node_modules/@applitools/core-base/dist/server/requests.js:310:26)\n    at async Object.getAccountInfo (/opt/hostedtoolcache/Python/3.8.18/x64/lib/python3.8/site-packages/applitools/core_universal/bin/core/__sea/node_modules/@applitools/core-base/dist/get-account-info.js:34:25)\n    at async Object.openEyes (/opt/hostedtoolcache/Python/3.8.18/x64/lib/python3.8/site-packages/applitools/core_universal/bin/core/__sea/dist/ufg/open-eyes.js:55:25)\n    at async getTypedEyes (/opt/hostedtoolcache/Python/3.8.18/x64/lib/python3.8/site-packages/applitools/core_universal/bin/core/__sea/dist/get-typed-eyes.js:9:20)\n    at async openEyes (/opt/hostedtoolcache/Python/3.8.18/x64/lib/python3.8/site-packages/applitools/core_universal/bin/core/__sea/dist/open-eyes.js:94:22)')</msg>
<msg time="2024-02-29T14:43:00.768405" level="FAIL">EyesLibraryError: Failed to run EyesLibrary
Traceback (most recent call last):
  File "/opt/hostedtoolcache/Python/3.8.18/x64/lib/python3.8/site-packages/EyesLibrary/__init__.py", line 266, in run_keyword
    return DynamicCore.run_keyword(self, name, args, kwargs)
  File "/opt/hostedtoolcache/Python/3.8.18/x64/lib/python3.8/site-packages/robotlibcore.py", line 133, in run_keyword
    return self.keywords[name](*args, **(kwargs or {}))
  File "/opt/hostedtoolcache/Python/3.8.18/x64/lib/python3.8/site-packages/EyesLibrary/keywords/session.py", line 145, in open
    return eyes.open(self.fetch_driver())
  File "/opt/hostedtoolcache/Python/3.8.18/x64/lib/python3.8/site-packages/applitools/common/eyes.py", line 291, in open
    self._open(app_name, test_name, viewport_size, driver)
  File "/opt/hostedtoolcache/Python/3.8.18/x64/lib/python3.8/site-packages/applitools/common/eyes.py", line 220, in _open
    self._eyes_ref = self._commands.manager_open_eyes(
  File "/opt/hostedtoolcache/Python/3.8.18/x64/lib/python3.8/site-packages/applitools/common/command_executor.py", line 156, in manager_open_eyes
    return self._checked_command(context, "EyesManager.openEyes", payload)
  File "/opt/hostedtoolcache/Python/3.8.18/x64/lib/python3.8/site-packages/applitools/common/command_executor.py", line 284, in _checked_command
    _check_error(response_payload)
  File "/opt/hostedtoolcache/Python/3.8.18/x64/lib/python3.8/site-packages/applitools/common/command_executor.py", line 294, in _check_error
    raise usdk_error
applitools.common.errors.USDKFailure: Request "getAccountInfo" [0--20edbb2b-5a2f-4b88-b5bb-de5781c2a650] that was sent to the address "[GET]https://eyesapi.applitools.com/api/sessions/renderinfo?apiKey=%3Capi-key%3E" failed due to unexpected status Unauthorized(401)
    at Object.afterResponse (/opt/hostedtoolcache/Python/3.8.18/x64/lib/python3.8/site-packages/applitools/core_universal/bin/core/__sea/node_modules/@applitools/core-base/dist/server/req-eyes.js:101:23)
    at /opt/hostedtoolcache/Python/3.8.18/x64/lib/python3.8/site-packages/applitools/core_universal/bin/core/__sea/node_modules/@applitools/req/dist/index.cjs:9828:97
    at process.processTicksAndRejections (node:internal/process/task_queues:95:5)
    at async req2 (/opt/hostedtoolcache/Python/3.8.18/x64/lib/python3.8/site-packages/applitools/core_universal/bin/core/__sea/node_modules/@applitools/req/dist/index.cjs:9729:18)
    at async req (/opt/hostedtoolcache/Python/3.8.18/x64/lib/python3.8/site-packages/applitools/core_universal/bin/core/__sea/node_modules/@applitools/req/dist/index.cjs:9640:12)
    at async getAccountInfo (/opt/hostedtoolcache/Python/3.8.18/x64/lib/python3.8/site-packages/applitools/core_universal/bin/core/__sea/node_modules/@applitools/core-base/dist/server/requests.js:310:26)
    at async Object.getAccountInfo (/opt/hostedtoolcache/Python/3.8.18/x64/lib/python3.8/site-packages/applitools/core_universal/bin/core/__sea/node_modules/@applitools/core-base/dist/get-account-info.js:34:25)
    at async Object.openEyes (/opt/hostedtoolcache/Python/3.8.18/x64/lib/python3.8/site-packages/applitools/core_universal/bin/core/__sea/dist/ufg/open-eyes.js:55:25)
    at async getTypedEyes (/opt/hostedtoolcache/Python/3.8.18/x64/lib/python3.8/site-packages/applitools/core_universal/bin/core/__sea/dist/get-typed-eyes.js:9:20)
    at async openEyes (/opt/hostedtoolcache/Python/3.8.18/x64/lib/python3.8/site-packages/applitools/core_universal/bin/core/__sea/dist/open-eyes.js:94:22)
</msg>
<arg>${TEST_NAME}</arg>
<arg>${VIEWPORT_SIZE}</arg>
<arg>${APP_NAME}</arg>
<arg>${HOST_OS}</arg>
<arg>${HOST_APP}</arg>
<arg>${MATCH_LEVEL}</arg>
<arg>${BASELINE_ENV_NAME}</arg>
<arg>${BATCH_NAME}</arg>
<tag>Check flow</tag>
<doc>Shared parameters section from `applitools.yaml` could be overwritten during `Eyes Open` call, see `Preconditions`.</doc>
<status status="FAIL" start="2024-02-29T14:42:59.780806" elapsed="0.988018">EyesLibraryError: Failed to run EyesLibrary
Traceback (most recent call last):
  File "/opt/hostedtoolcache/Python/3.8.18/x64/lib/python3.8/site-packages/EyesLibrary/__init__.py", line 266, in run_keyword
    return DynamicCore.run_keyword(self, name, args, kwargs)
  File "/opt/hostedtoolcache/Python/3.8.18/x64/lib/python3.8/site-packages/robotlibcore.py", line 133, in run_keyword
    return self.keywords[name](*args, **(kwargs or {}))
  File "/opt/hostedtoolcache/Python/3.8.18/x64/lib/python3.8/site-packages/EyesLibrary/keywords/session.py", line 145, in open
    return eyes.open(self.fetch_driver())
  File "/opt/hostedtoolcache/Python/3.8.18/x64/lib/python3.8/site-packages/applitools/common/eyes.py", line 291, in open
    self._open(app_name, test_name, viewport_size, driver)
  File "/opt/hostedtoolcache/Python/3.8.18/x64/lib/python3.8/site-packages/applitools/common/eyes.py", line 220, in _open
    self._eyes_ref = self._commands.manager_open_eyes(
  File "/opt/hostedtoolcache/Python/3.8.18/x64/lib/python3.8/site-packages/applitools/common/command_executor.py", line 156, in manager_open_eyes
    return self._checked_command(context, "EyesManager.openEyes", payload)
    [ Message content over the limit has been removed. ]
    at async req2 (/opt/hostedtoolcache/Python/3.8.18/x64/lib/python3.8/site-packages/applitools/core_universal/bin/core/__sea/node_modules/@applitools/req/dist/index.cjs:9729:18)
    at async req (/opt/hostedtoolcache/Python/3.8.18/x64/lib/python3.8/site-packages/applitools/core_universal/bin/core/__sea/node_modules/@applitools/req/dist/index.cjs:9640:12)
    at async getAccountInfo (/opt/hostedtoolcache/Python/3.8.18/x64/lib/python3.8/site-packages/applitools/core_universal/bin/core/__sea/node_modules/@applitools/core-base/dist/server/requests.js:310:26)
    at async Object.getAccountInfo (/opt/hostedtoolcache/Python/3.8.18/x64/lib/python3.8/site-packages/applitools/core_universal/bin/core/__sea/node_modules/@applitools/core-base/dist/get-account-info.js:34:25)
    at async Object.openEyes (/opt/hostedtoolcache/Python/3.8.18/x64/lib/python3.8/site-packages/applitools/core_universal/bin/core/__sea/dist/ufg/open-eyes.js:55:25)
    at async getTypedEyes (/opt/hostedtoolcache/Python/3.8.18/x64/lib/python3.8/site-packages/applitools/core_universal/bin/core/__sea/dist/get-typed-eyes.js:9:20)
    at async openEyes (/opt/hostedtoolcache/Python/3.8.18/x64/lib/python3.8/site-packages/applitools/core_universal/bin/core/__sea/dist/open-eyes.js:94:22)</status>
</kw>
<status status="FAIL" start="2024-02-29T14:42:48.078612" elapsed="12.691343">EyesLibraryError: Failed to run EyesLibrary
Traceback (most recent call last):
  File "/opt/hostedtoolcache/Python/3.8.18/x64/lib/python3.8/site-packages/EyesLibrary/__init__.py", line 266, in run_keyword
    return DynamicCore.run_keyword(self, name, args, kwargs)
  File "/opt/hostedtoolcache/Python/3.8.18/x64/lib/python3.8/site-packages/robotlibcore.py", line 133, in run_keyword
    return self.keywords[name](*args, **(kwargs or {}))
  File "/opt/hostedtoolcache/Python/3.8.18/x64/lib/python3.8/site-packages/EyesLibrary/keywords/session.py", line 145, in open
    return eyes.open(self.fetch_driver())
  File "/opt/hostedtoolcache/Python/3.8.18/x64/lib/python3.8/site-packages/applitools/common/eyes.py", line 291, in open
    self._open(app_name, test_name, viewport_size, driver)
  File "/opt/hostedtoolcache/Python/3.8.18/x64/lib/python3.8/site-packages/applitools/common/eyes.py", line 220, in _open
    self._eyes_ref = self._commands.manager_open_eyes(
  File "/opt/hostedtoolcache/Python/3.8.18/x64/lib/python3.8/site-packages/applitools/common/command_executor.py", line 156, in manager_open_eyes
    return self._checked_command(context, "EyesManager.openEyes", payload)
    [ Message content over the limit has been removed. ]
    at async req2 (/opt/hostedtoolcache/Python/3.8.18/x64/lib/python3.8/site-packages/applitools/core_universal/bin/core/__sea/node_modules/@applitools/req/dist/index.cjs:9729:18)
    at async req (/opt/hostedtoolcache/Python/3.8.18/x64/lib/python3.8/site-packages/applitools/core_universal/bin/core/__sea/node_modules/@applitools/req/dist/index.cjs:9640:12)
    at async getAccountInfo (/opt/hostedtoolcache/Python/3.8.18/x64/lib/python3.8/site-packages/applitools/core_universal/bin/core/__sea/node_modules/@applitools/core-base/dist/server/requests.js:310:26)
    at async Object.getAccountInfo (/opt/hostedtoolcache/Python/3.8.18/x64/lib/python3.8/site-packages/applitools/core_universal/bin/core/__sea/node_modules/@applitools/core-base/dist/get-account-info.js:34:25)
    at async Object.openEyes (/opt/hostedtoolcache/Python/3.8.18/x64/lib/python3.8/site-packages/applitools/core_universal/bin/core/__sea/dist/ufg/open-eyes.js:55:25)
    at async getTypedEyes (/opt/hostedtoolcache/Python/3.8.18/x64/lib/python3.8/site-packages/applitools/core_universal/bin/core/__sea/dist/get-typed-eyes.js:9:20)
    at async openEyes (/opt/hostedtoolcache/Python/3.8.18/x64/lib/python3.8/site-packages/applitools/core_universal/bin/core/__sea/dist/open-eyes.js:94:22)</status>
</kw>
<kw name="After Visual Tests" owner="common_keywords" type="TEARDOWN">
<kw name="Close All Browsers" owner="SeleniumLibrary">
<doc>Closes all open browsers and resets the browser cache.</doc>
<status status="PASS" start="2024-02-29T14:43:00.771529" elapsed="0.065019"/>
</kw>
<status status="PASS" start="2024-02-29T14:43:00.770800" elapsed="0.066033"/>
</kw>
<status status="FAIL" start="2024-02-29T14:42:48.077278" elapsed="12.759696">Setup failed:
EyesLibraryError: Failed to run EyesLibrary
Traceback (most recent call last):
  File "/opt/hostedtoolcache/Python/3.8.18/x64/lib/python3.8/site-packages/EyesLibrary/__init__.py", line 266, in run_keyword
    return DynamicCore.run_keyword(self, name, args, kwargs)
  File "/opt/hostedtoolcache/Python/3.8.18/x64/lib/python3.8/site-packages/robotlibcore.py", line 133, in run_keyword
    return self.keywords[name](*args, **(kwargs or {}))
  File "/opt/hostedtoolcache/Python/3.8.18/x64/lib/python3.8/site-packages/EyesLibrary/keywords/session.py", line 145, in open
    return eyes.open(self.fetch_driver())
  File "/opt/hostedtoolcache/Python/3.8.18/x64/lib/python3.8/site-packages/applitools/common/eyes.py", line 291, in open
    self._open(app_name, test_name, viewport_size, driver)
  File "/opt/hostedtoolcache/Python/3.8.18/x64/lib/python3.8/site-packages/applitools/common/eyes.py", line 220, in _open
    self._eyes_ref = self._commands.manager_open_eyes(
  File "/opt/hostedtoolcache/Python/3.8.18/x64/lib/python3.8/site-packages/applitools/common/command_executor.py", line 156, in manager_open_eyes
    return self._checked_command(context, "EyesManager.openEyes", payload)
    [ Message content over the limit has been removed. ]
    at async req2 (/opt/hostedtoolcache/Python/3.8.18/x64/lib/python3.8/site-packages/applitools/core_universal/bin/core/__sea/node_modules/@applitools/req/dist/index.cjs:9729:18)
    at async req (/opt/hostedtoolcache/Python/3.8.18/x64/lib/python3.8/site-packages/applitools/core_universal/bin/core/__sea/node_modules/@applitools/req/dist/index.cjs:9640:12)
    at async getAccountInfo (/opt/hostedtoolcache/Python/3.8.18/x64/lib/python3.8/site-packages/applitools/core_universal/bin/core/__sea/node_modules/@applitools/core-base/dist/server/requests.js:310:26)
    at async Object.getAccountInfo (/opt/hostedtoolcache/Python/3.8.18/x64/lib/python3.8/site-packages/applitools/core_universal/bin/core/__sea/node_modules/@applitools/core-base/dist/get-account-info.js:34:25)
    at async Object.openEyes (/opt/hostedtoolcache/Python/3.8.18/x64/lib/python3.8/site-packages/applitools/core_universal/bin/core/__sea/dist/ufg/open-eyes.js:55:25)
    at async getTypedEyes (/opt/hostedtoolcache/Python/3.8.18/x64/lib/python3.8/site-packages/applitools/core_universal/bin/core/__sea/dist/get-typed-eyes.js:9:20)
    at async openEyes (/opt/hostedtoolcache/Python/3.8.18/x64/lib/python3.8/site-packages/applitools/core_universal/bin/core/__sea/dist/open-eyes.js:94:22)</status>
</test>
<meta name="Applitools TestResults Path">/tmp/tmphxy5mr65/EyesTestResults-8ef2c774db0e490299b408fa4cf694d2.json</meta>
<status status="FAIL" start="2024-02-29T14:42:46.513000" elapsed="14.324132"/>
</suite>
<suite id="s1-s2" name="Visual Test 2" source="/home/runner/work/robot-applitools-tests/robot-applitools-tests/tests/visual_test_2.robot">
<test id="s1-s2-t1" name="Autonomous Page" line="10">
<kw name="Before Visual Tests" owner="common_keywords" type="SETUP">
<kw name="Open Browser" owner="SeleniumLibrary">
<msg time="2024-02-29T14:42:48.094369" level="INFO">Opening browser 'headless Chrome' to base url 'https://applitools.com/'.</msg>
<arg>${BASE_URL}</arg>
<arg>${HEADLESS} ${BROWSER}</arg>
<doc>Opens a new browser instance to the optional ``url``.</doc>
<status status="PASS" start="2024-02-29T14:42:48.093925" elapsed="11.567871"/>
</kw>
<kw name="Eyes Open" owner="EyesLibrary">
<msg time="2024-02-29T14:43:00.484399" level="ERROR">Re-raising an error received from SDK server: USDKFailure('Request "getAccountInfo" [0--df7a502b-23e7-4a26-a258-b38207ca22d6] that was sent to the address "[GET]https://eyesapi.applitools.com/api/sessions/renderinfo?apiKey=%3Capi-key%3E" failed due to unexpected status Unauthorized(401)', '    at Object.afterResponse (/opt/hostedtoolcache/Python/3.8.18/x64/lib/python3.8/site-packages/applitools/core_universal/bin/core/__sea/node_modules/@applitools/core-base/dist/server/req-eyes.js:101:23)\n    at /opt/hostedtoolcache/Python/3.8.18/x64/lib/python3.8/site-packages/applitools/core_universal/bin/core/__sea/node_modules/@applitools/req/dist/index.cjs:9828:97\n    at process.processTicksAndRejections (node:internal/process/task_queues:95:5)\n    at async req2 (/opt/hostedtoolcache/Python/3.8.18/x64/lib/python3.8/site-packages/applitools/core_universal/bin/core/__sea/node_modules/@applitools/req/dist/index.cjs:9729:18)\n    at async req (/opt/hostedtoolcache/Python/3.8.18/x64/lib/python3.8/site-packages/applitools/core_universal/bin/core/__sea/node_modules/@applitools/req/dist/index.cjs:9640:12)\n    at async getAccountInfo (/opt/hostedtoolcache/Python/3.8.18/x64/lib/python3.8/site-packages/applitools/core_universal/bin/core/__sea/node_modules/@applitools/core-base/dist/server/requests.js:310:26)\n    at async Object.getAccountInfo (/opt/hostedtoolcache/Python/3.8.18/x64/lib/python3.8/site-packages/applitools/core_universal/bin/core/__sea/node_modules/@applitools/core-base/dist/get-account-info.js:34:25)\n    at async Object.openEyes (/opt/hostedtoolcache/Python/3.8.18/x64/lib/python3.8/site-packages/applitools/core_universal/bin/core/__sea/dist/ufg/open-eyes.js:55:25)\n    at async getTypedEyes (/opt/hostedtoolcache/Python/3.8.18/x64/lib/python3.8/site-packages/applitools/core_universal/bin/core/__sea/dist/get-typed-eyes.js:9:20)\n    at async openEyes (/opt/hostedtoolcache/Python/3.8.18/x64/lib/python3.8/site-packages/applitools/core_universal/bin/core/__sea/dist/open-eyes.js:94:22)')</msg>
<msg time="2024-02-29T14:43:00.486166" level="FAIL">EyesLibraryError: Failed to run EyesLibrary
Traceback (most recent call last):
  File "/opt/hostedtoolcache/Python/3.8.18/x64/lib/python3.8/site-packages/EyesLibrary/__init__.py", line 266, in run_keyword
    return DynamicCore.run_keyword(self, name, args, kwargs)
  File "/opt/hostedtoolcache/Python/3.8.18/x64/lib/python3.8/site-packages/robotlibcore.py", line 133, in run_keyword
    return self.keywords[name](*args, **(kwargs or {}))
  File "/opt/hostedtoolcache/Python/3.8.18/x64/lib/python3.8/site-packages/EyesLibrary/keywords/session.py", line 145, in open
    return eyes.open(self.fetch_driver())
  File "/opt/hostedtoolcache/Python/3.8.18/x64/lib/python3.8/site-packages/applitools/common/eyes.py", line 291, in open
    self._open(app_name, test_name, viewport_size, driver)
  File "/opt/hostedtoolcache/Python/3.8.18/x64/lib/python3.8/site-packages/applitools/common/eyes.py", line 220, in _open
    self._eyes_ref = self._commands.manager_open_eyes(
  File "/opt/hostedtoolcache/Python/3.8.18/x64/lib/python3.8/site-packages/applitools/common/command_executor.py", line 156, in manager_open_eyes
    return self._checked_command(context, "EyesManager.openEyes", payload)
  File "/opt/hostedtoolcache/Python/3.8.18/x64/lib/python3.8/site-packages/applitools/common/command_executor.py", line 284, in _checked_command
    _check_error(response_payload)
  File "/opt/hostedtoolcache/Python/3.8.18/x64/lib/python3.8/site-packages/applitools/common/command_executor.py", line 294, in _check_error
    raise usdk_error
applitools.common.errors.USDKFailure: Request "getAccountInfo" [0--df7a502b-23e7-4a26-a258-b38207ca22d6] that was sent to the address "[GET]https://eyesapi.applitools.com/api/sessions/renderinfo?apiKey=%3Capi-key%3E" failed due to unexpected status Unauthorized(401)
    at Object.afterResponse (/opt/hostedtoolcache/Python/3.8.18/x64/lib/python3.8/site-packages/applitools/core_universal/bin/core/__sea/node_modules/@applitools/core-base/dist/server/req-eyes.js:101:23)
    at /opt/hostedtoolcache/Python/3.8.18/x64/lib/python3.8/site-packages/applitools/core_universal/bin/core/__sea/node_modules/@applitools/req/dist/index.cjs:9828:97
    at process.processTicksAndRejections (node:internal/process/task_queues:95:5)
    at async req2 (/opt/hostedtoolcache/Python/3.8.18/x64/lib/python3.8/site-packages/applitools/core_universal/bin/core/__sea/node_modules/@applitools/req/dist/index.cjs:9729:18)
    at async req (/opt/hostedtoolcache/Python/3.8.18/x64/lib/python3.8/site-packages/applitools/core_universal/bin/core/__sea/node_modules/@applitools/req/dist/index.cjs:9640:12)
    at async getAccountInfo (/opt/hostedtoolcache/Python/3.8.18/x64/lib/python3.8/site-packages/applitools/core_universal/bin/core/__sea/node_modules/@applitools/core-base/dist/server/requests.js:310:26)
    at async Object.getAccountInfo (/opt/hostedtoolcache/Python/3.8.18/x64/lib/python3.8/site-packages/applitools/core_universal/bin/core/__sea/node_modules/@applitools/core-base/dist/get-account-info.js:34:25)
    at async Object.openEyes (/opt/hostedtoolcache/Python/3.8.18/x64/lib/python3.8/site-packages/applitools/core_universal/bin/core/__sea/dist/ufg/open-eyes.js:55:25)
    at async getTypedEyes (/opt/hostedtoolcache/Python/3.8.18/x64/lib/python3.8/site-packages/applitools/core_universal/bin/core/__sea/dist/get-typed-eyes.js:9:20)
    at async openEyes (/opt/hostedtoolcache/Python/3.8.18/x64/lib/python3.8/site-packages/applitools/core_universal/bin/core/__sea/dist/open-eyes.js:94:22)
</msg>
<arg>${TEST_NAME}</arg>
<arg>${VIEWPORT_SIZE}</arg>
<arg>${APP_NAME}</arg>
<arg>${HOST_OS}</arg>
<arg>${HOST_APP}</arg>
<arg>${MATCH_LEVEL}</arg>
<arg>${BASELINE_ENV_NAME}</arg>
<arg>${BATCH_NAME}</arg>
<tag>Check flow</tag>
<doc>Shared parameters section from `applitools.yaml` could be overwritten during `Eyes Open` call, see `Preconditions`.</doc>
<status status="FAIL" start="2024-02-29T14:42:59.662398" elapsed="0.824187">EyesLibraryError: Failed to run EyesLibrary
Traceback (most recent call last):
  File "/opt/hostedtoolcache/Python/3.8.18/x64/lib/python3.8/site-packages/EyesLibrary/__init__.py", line 266, in run_keyword
    return DynamicCore.run_keyword(self, name, args, kwargs)
  File "/opt/hostedtoolcache/Python/3.8.18/x64/lib/python3.8/site-packages/robotlibcore.py", line 133, in run_keyword
    return self.keywords[name](*args, **(kwargs or {}))
  File "/opt/hostedtoolcache/Python/3.8.18/x64/lib/python3.8/site-packages/EyesLibrary/keywords/session.py", line 145, in open
    return eyes.open(self.fetch_driver())
  File "/opt/hostedtoolcache/Python/3.8.18/x64/lib/python3.8/site-packages/applitools/common/eyes.py", line 291, in open
    self._open(app_name, test_name, viewport_size, driver)
  File "/opt/hostedtoolcache/Python/3.8.18/x64/lib/python3.8/site-packages/applitools/common/eyes.py", line 220, in _open
    self._eyes_ref = self._commands.manager_open_eyes(
  File "/opt/hostedtoolcache/Python/3.8.18/x64/lib/python3.8/site-packages/applitools/common/command_executor.py", line 156, in manager_open_eyes
    return self._checked_command(context, "EyesManager.openEyes", payload)
    [ Message content over the limit has been removed. ]
    at async req2 (/opt/hostedtoolcache/Python/3.8.18/x64/lib/python3.8/site-packages/applitools/core_universal/bin/core/__sea/node_modules/@applitools/req/dist/index.cjs:9729:18)
    at async req (/opt/hostedtoolcache/Python/3.8.18/x64/lib/python3.8/site-packages/applitools/core_universal/bin/core/__sea/node_modules/@applitools/req/dist/index.cjs:9640:12)
    at async getAccountInfo (/opt/hostedtoolcache/Python/3.8.18/x64/lib/python3.8/site-packages/applitools/core_universal/bin/core/__sea/node_modules/@applitools/core-base/dist/server/requests.js:310:26)
    at async Object.getAccountInfo (/opt/hostedtoolcache/Python/3.8.18/x64/lib/python3.8/site-packages/applitools/core_universal/bin/core/__sea/node_modules/@applitools/core-base/dist/get-account-info.js:34:25)
    at async Object.openEyes (/opt/hostedtoolcache/Python/3.8.18/x64/lib/python3.8/site-packages/applitools/core_universal/bin/core/__sea/dist/ufg/open-eyes.js:55:25)
    at async getTypedEyes (/opt/hostedtoolcache/Python/3.8.18/x64/lib/python3.8/site-packages/applitools/core_universal/bin/core/__sea/dist/get-typed-eyes.js:9:20)
    at async openEyes (/opt/hostedtoolcache/Python/3.8.18/x64/lib/python3.8/site-packages/applitools/core_universal/bin/core/__sea/dist/open-eyes.js:94:22)</status>
</kw>
<status status="FAIL" start="2024-02-29T14:42:48.092689" elapsed="12.394755">EyesLibraryError: Failed to run EyesLibrary
Traceback (most recent call last):
  File "/opt/hostedtoolcache/Python/3.8.18/x64/lib/python3.8/site-packages/EyesLibrary/__init__.py", line 266, in run_keyword
    return DynamicCore.run_keyword(self, name, args, kwargs)
  File "/opt/hostedtoolcache/Python/3.8.18/x64/lib/python3.8/site-packages/robotlibcore.py", line 133, in run_keyword
    return self.keywords[name](*args, **(kwargs or {}))
  File "/opt/hostedtoolcache/Python/3.8.18/x64/lib/python3.8/site-packages/EyesLibrary/keywords/session.py", line 145, in open
    return eyes.open(self.fetch_driver())
  File "/opt/hostedtoolcache/Python/3.8.18/x64/lib/python3.8/site-packages/applitools/common/eyes.py", line 291, in open
    self._open(app_name, test_name, viewport_size, driver)
  File "/opt/hostedtoolcache/Python/3.8.18/x64/lib/python3.8/site-packages/applitools/common/eyes.py", line 220, in _open
    self._eyes_ref = self._commands.manager_open_eyes(
  File "/opt/hostedtoolcache/Python/3.8.18/x64/lib/python3.8/site-packages/applitools/common/command_executor.py", line 156, in manager_open_eyes
    return self._checked_command(context, "EyesManager.openEyes", payload)
    [ Message content over the limit has been removed. ]
    at async req2 (/opt/hostedtoolcache/Python/3.8.18/x64/lib/python3.8/site-packages/applitools/core_universal/bin/core/__sea/node_modules/@applitools/req/dist/index.cjs:9729:18)
    at async req (/opt/hostedtoolcache/Python/3.8.18/x64/lib/python3.8/site-packages/applitools/core_universal/bin/core/__sea/node_modules/@applitools/req/dist/index.cjs:9640:12)
    at async getAccountInfo (/opt/hostedtoolcache/Python/3.8.18/x64/lib/python3.8/site-packages/applitools/core_universal/bin/core/__sea/node_modules/@applitools/core-base/dist/server/requests.js:310:26)
    at async Object.getAccountInfo (/opt/hostedtoolcache/Python/3.8.18/x64/lib/python3.8/site-packages/applitools/core_universal/bin/core/__sea/node_modules/@applitools/core-base/dist/get-account-info.js:34:25)
    at async Object.openEyes (/opt/hostedtoolcache/Python/3.8.18/x64/lib/python3.8/site-packages/applitools/core_universal/bin/core/__sea/dist/ufg/open-eyes.js:55:25)
    at async getTypedEyes (/opt/hostedtoolcache/Python/3.8.18/x64/lib/python3.8/site-packages/applitools/core_universal/bin/core/__sea/dist/get-typed-eyes.js:9:20)
    at async openEyes (/opt/hostedtoolcache/Python/3.8.18/x64/lib/python3.8/site-packages/applitools/core_universal/bin/core/__sea/dist/open-eyes.js:94:22)</status>
</kw>
<kw name="After Visual Tests" owner="common_keywords" type="TEARDOWN">
<kw name="Close All Browsers" owner="SeleniumLibrary">
<doc>Closes all open browsers and resets the browser cache.</doc>
<status status="PASS" start="2024-02-29T14:43:00.488489" elapsed="0.068264"/>
</kw>
<status status="PASS" start="2024-02-29T14:43:00.488013" elapsed="0.069043"/>
</kw>
<status status="FAIL" start="2024-02-29T14:42:48.091396" elapsed="12.465820">Setup failed:
EyesLibraryError: Failed to run EyesLibrary
Traceback (most recent call last):
  File "/opt/hostedtoolcache/Python/3.8.18/x64/lib/python3.8/site-packages/EyesLibrary/__init__.py", line 266, in run_keyword
    return DynamicCore.run_keyword(self, name, args, kwargs)
  File "/opt/hostedtoolcache/Python/3.8.18/x64/lib/python3.8/site-packages/robotlibcore.py", line 133, in run_keyword
    return self.keywords[name](*args, **(kwargs or {}))
  File "/opt/hostedtoolcache/Python/3.8.18/x64/lib/python3.8/site-packages/EyesLibrary/keywords/session.py", line 145, in open
    return eyes.open(self.fetch_driver())
  File "/opt/hostedtoolcache/Python/3.8.18/x64/lib/python3.8/site-packages/applitools/common/eyes.py", line 291, in open
    self._open(app_name, test_name, viewport_size, driver)
  File "/opt/hostedtoolcache/Python/3.8.18/x64/lib/python3.8/site-packages/applitools/common/eyes.py", line 220, in _open
    self._eyes_ref = self._commands.manager_open_eyes(
  File "/opt/hostedtoolcache/Python/3.8.18/x64/lib/python3.8/site-packages/applitools/common/command_executor.py", line 156, in manager_open_eyes
    return self._checked_command(context, "EyesManager.openEyes", payload)
    [ Message content over the limit has been removed. ]
    at async req2 (/opt/hostedtoolcache/Python/3.8.18/x64/lib/python3.8/site-packages/applitools/core_universal/bin/core/__sea/node_modules/@applitools/req/dist/index.cjs:9729:18)
    at async req (/opt/hostedtoolcache/Python/3.8.18/x64/lib/python3.8/site-packages/applitools/core_universal/bin/core/__sea/node_modules/@applitools/req/dist/index.cjs:9640:12)
    at async getAccountInfo (/opt/hostedtoolcache/Python/3.8.18/x64/lib/python3.8/site-packages/applitools/core_universal/bin/core/__sea/node_modules/@applitools/core-base/dist/server/requests.js:310:26)
    at async Object.getAccountInfo (/opt/hostedtoolcache/Python/3.8.18/x64/lib/python3.8/site-packages/applitools/core_universal/bin/core/__sea/node_modules/@applitools/core-base/dist/get-account-info.js:34:25)
    at async Object.openEyes (/opt/hostedtoolcache/Python/3.8.18/x64/lib/python3.8/site-packages/applitools/core_universal/bin/core/__sea/dist/ufg/open-eyes.js:55:25)
    at async getTypedEyes (/opt/hostedtoolcache/Python/3.8.18/x64/lib/python3.8/site-packages/applitools/core_universal/bin/core/__sea/dist/get-typed-eyes.js:9:20)
    at async openEyes (/opt/hostedtoolcache/Python/3.8.18/x64/lib/python3.8/site-packages/applitools/core_universal/bin/core/__sea/dist/open-eyes.js:94:22)</status>
</test>
<meta name="Applitools TestResults Path">/tmp/tmpvrm6kon2/EyesTestResults-70a1277c280745ca9fb131dc7fa80d2c.json</meta>
<status status="FAIL" start="2024-02-29T14:42:46.518207" elapsed="14.040090"/>
</suite>
<suite id="s1-s3" name="Visual Test 3" source="/home/runner/work/robot-applitools-tests/robot-applitools-tests/tests/visual_test_3.robot">
<test id="s1-s3-t1" name="Eyes Page" line="10">
<kw name="Before Visual Tests" owner="common_keywords" type="SETUP">
<kw name="Open Browser" owner="SeleniumLibrary">
<msg time="2024-02-29T14:42:48.104969" level="INFO">Opening browser 'headless Chrome' to base url 'https://applitools.com/'.</msg>
<arg>${BASE_URL}</arg>
<arg>${HEADLESS} ${BROWSER}</arg>
<doc>Opens a new browser instance to the optional ``url``.</doc>
<status status="PASS" start="2024-02-29T14:42:48.104483" elapsed="11.679338"/>
</kw>
<kw name="Eyes Open" owner="EyesLibrary">
<msg time="2024-02-29T14:43:00.765575" level="ERROR">Re-raising an error received from SDK server: USDKFailure('Request "getAccountInfo" [0--f9ae0e72-c1ab-4601-88c4-ad9cf2b4f1bc] that was sent to the address "[GET]https://eyesapi.applitools.com/api/sessions/renderinfo?apiKey=%3Capi-key%3E" failed due to unexpected status Unauthorized(401)', '    at Object.afterResponse (/opt/hostedtoolcache/Python/3.8.18/x64/lib/python3.8/site-packages/applitools/core_universal/bin/core/__sea/node_modules/@applitools/core-base/dist/server/req-eyes.js:101:23)\n    at /opt/hostedtoolcache/Python/3.8.18/x64/lib/python3.8/site-packages/applitools/core_universal/bin/core/__sea/node_modules/@applitools/req/dist/index.cjs:9828:97\n    at process.processTicksAndRejections (node:internal/process/task_queues:95:5)\n    at async req2 (/opt/hostedtoolcache/Python/3.8.18/x64/lib/python3.8/site-packages/applitools/core_universal/bin/core/__sea/node_modules/@applitools/req/dist/index.cjs:9729:18)\n    at async req (/opt/hostedtoolcache/Python/3.8.18/x64/lib/python3.8/site-packages/applitools/core_universal/bin/core/__sea/node_modules/@applitools/req/dist/index.cjs:9640:12)\n    at async getAccountInfo (/opt/hostedtoolcache/Python/3.8.18/x64/lib/python3.8/site-packages/applitools/core_universal/bin/core/__sea/node_modules/@applitools/core-base/dist/server/requests.js:310:26)\n    at async Object.getAccountInfo (/opt/hostedtoolcache/Python/3.8.18/x64/lib/python3.8/site-packages/applitools/core_universal/bin/core/__sea/node_modules/@applitools/core-base/dist/get-account-info.js:34:25)\n    at async Object.openEyes (/opt/hostedtoolcache/Python/3.8.18/x64/lib/python3.8/site-packages/applitools/core_universal/bin/core/__sea/dist/ufg/open-eyes.js:55:25)\n    at async getTypedEyes (/opt/hostedtoolcache/Python/3.8.18/x64/lib/python3.8/site-packages/applitools/core_universal/bin/core/__sea/dist/get-typed-eyes.js:9:20)\n    at async openEyes (/opt/hostedtoolcache/Python/3.8.18/x64/lib/python3.8/site-packages/applitools/core_universal/bin/core/__sea/dist/open-eyes.js:94:22)')</msg>
<msg time="2024-02-29T14:43:00.767553" level="FAIL">EyesLibraryError: Failed to run EyesLibrary
Traceback (most recent call last):
  File "/opt/hostedtoolcache/Python/3.8.18/x64/lib/python3.8/site-packages/EyesLibrary/__init__.py", line 266, in run_keyword
    return DynamicCore.run_keyword(self, name, args, kwargs)
  File "/opt/hostedtoolcache/Python/3.8.18/x64/lib/python3.8/site-packages/robotlibcore.py", line 133, in run_keyword
    return self.keywords[name](*args, **(kwargs or {}))
  File "/opt/hostedtoolcache/Python/3.8.18/x64/lib/python3.8/site-packages/EyesLibrary/keywords/session.py", line 145, in open
    return eyes.open(self.fetch_driver())
  File "/opt/hostedtoolcache/Python/3.8.18/x64/lib/python3.8/site-packages/applitools/common/eyes.py", line 291, in open
    self._open(app_name, test_name, viewport_size, driver)
  File "/opt/hostedtoolcache/Python/3.8.18/x64/lib/python3.8/site-packages/applitools/common/eyes.py", line 220, in _open
    self._eyes_ref = self._commands.manager_open_eyes(
  File "/opt/hostedtoolcache/Python/3.8.18/x64/lib/python3.8/site-packages/applitools/common/command_executor.py", line 156, in manager_open_eyes
    return self._checked_command(context, "EyesManager.openEyes", payload)
  File "/opt/hostedtoolcache/Python/3.8.18/x64/lib/python3.8/site-packages/applitools/common/command_executor.py", line 284, in _checked_command
    _check_error(response_payload)
  File "/opt/hostedtoolcache/Python/3.8.18/x64/lib/python3.8/site-packages/applitools/common/command_executor.py", line 294, in _check_error
    raise usdk_error
applitools.common.errors.USDKFailure: Request "getAccountInfo" [0--f9ae0e72-c1ab-4601-88c4-ad9cf2b4f1bc] that was sent to the address "[GET]https://eyesapi.applitools.com/api/sessions/renderinfo?apiKey=%3Capi-key%3E" failed due to unexpected status Unauthorized(401)
    at Object.afterResponse (/opt/hostedtoolcache/Python/3.8.18/x64/lib/python3.8/site-packages/applitools/core_universal/bin/core/__sea/node_modules/@applitools/core-base/dist/server/req-eyes.js:101:23)
    at /opt/hostedtoolcache/Python/3.8.18/x64/lib/python3.8/site-packages/applitools/core_universal/bin/core/__sea/node_modules/@applitools/req/dist/index.cjs:9828:97
    at process.processTicksAndRejections (node:internal/process/task_queues:95:5)
    at async req2 (/opt/hostedtoolcache/Python/3.8.18/x64/lib/python3.8/site-packages/applitools/core_universal/bin/core/__sea/node_modules/@applitools/req/dist/index.cjs:9729:18)
    at async req (/opt/hostedtoolcache/Python/3.8.18/x64/lib/python3.8/site-packages/applitools/core_universal/bin/core/__sea/node_modules/@applitools/req/dist/index.cjs:9640:12)
    at async getAccountInfo (/opt/hostedtoolcache/Python/3.8.18/x64/lib/python3.8/site-packages/applitools/core_universal/bin/core/__sea/node_modules/@applitools/core-base/dist/server/requests.js:310:26)
    at async Object.getAccountInfo (/opt/hostedtoolcache/Python/3.8.18/x64/lib/python3.8/site-packages/applitools/core_universal/bin/core/__sea/node_modules/@applitools/core-base/dist/get-account-info.js:34:25)
    at async Object.openEyes (/opt/hostedtoolcache/Python/3.8.18/x64/lib/python3.8/site-packages/applitools/core_universal/bin/core/__sea/dist/ufg/open-eyes.js:55:25)
    at async getTypedEyes (/opt/hostedtoolcache/Python/3.8.18/x64/lib/python3.8/site-packages/applitools/core_universal/bin/core/__sea/dist/get-typed-eyes.js:9:20)
    at async openEyes (/opt/hostedtoolcache/Python/3.8.18/x64/lib/python3.8/site-packages/applitools/core_universal/bin/core/__sea/dist/open-eyes.js:94:22)
</msg>
<arg>${TEST_NAME}</arg>
<arg>${VIEWPORT_SIZE}</arg>
<arg>${APP_NAME}</arg>
<arg>${HOST_OS}</arg>
<arg>${HOST_APP}</arg>
<arg>${MATCH_LEVEL}</arg>
<arg>${BASELINE_ENV_NAME}</arg>
<arg>${BATCH_NAME}</arg>
<tag>Check flow</tag>
<doc>Shared parameters section from `applitools.yaml` could be overwritten during `Eyes Open` call, see `Preconditions`.</doc>
<status status="FAIL" start="2024-02-29T14:42:59.784543" elapsed="0.983470">EyesLibraryError: Failed to run EyesLibrary
Traceback (most recent call last):
  File "/opt/hostedtoolcache/Python/3.8.18/x64/lib/python3.8/site-packages/EyesLibrary/__init__.py", line 266, in run_keyword
    return DynamicCore.run_keyword(self, name, args, kwargs)
  File "/opt/hostedtoolcache/Python/3.8.18/x64/lib/python3.8/site-packages/robotlibcore.py", line 133, in run_keyword
    return self.keywords[name](*args, **(kwargs or {}))
  File "/opt/hostedtoolcache/Python/3.8.18/x64/lib/python3.8/site-packages/EyesLibrary/keywords/session.py", line 145, in open
    return eyes.open(self.fetch_driver())
  File "/opt/hostedtoolcache/Python/3.8.18/x64/lib/python3.8/site-packages/applitools/common/eyes.py", line 291, in open
    self._open(app_name, test_name, viewport_size, driver)
  File "/opt/hostedtoolcache/Python/3.8.18/x64/lib/python3.8/site-packages/applitools/common/eyes.py", line 220, in _open
    self._eyes_ref = self._commands.manager_open_eyes(
  File "/opt/hostedtoolcache/Python/3.8.18/x64/lib/python3.8/site-packages/applitools/common/command_executor.py", line 156, in manager_open_eyes
    return self._checked_command(context, "EyesManager.openEyes", payload)
    [ Message content over the limit has been removed. ]
    at async req2 (/opt/hostedtoolcache/Python/3.8.18/x64/lib/python3.8/site-packages/applitools/core_universal/bin/core/__sea/node_modules/@applitools/req/dist/index.cjs:9729:18)
    at async req (/opt/hostedtoolcache/Python/3.8.18/x64/lib/python3.8/site-packages/applitools/core_universal/bin/core/__sea/node_modules/@applitools/req/dist/index.cjs:9640:12)
    at async getAccountInfo (/opt/hostedtoolcache/Python/3.8.18/x64/lib/python3.8/site-packages/applitools/core_universal/bin/core/__sea/node_modules/@applitools/core-base/dist/server/requests.js:310:26)
    at async Object.getAccountInfo (/opt/hostedtoolcache/Python/3.8.18/x64/lib/python3.8/site-packages/applitools/core_universal/bin/core/__sea/node_modules/@applitools/core-base/dist/get-account-info.js:34:25)
    at async Object.openEyes (/opt/hostedtoolcache/Python/3.8.18/x64/lib/python3.8/site-packages/applitools/core_universal/bin/core/__sea/dist/ufg/open-eyes.js:55:25)
    at async getTypedEyes (/opt/hostedtoolcache/Python/3.8.18/x64/lib/python3.8/site-packages/applitools/core_universal/bin/core/__sea/dist/get-typed-eyes.js:9:20)
    at async openEyes (/opt/hostedtoolcache/Python/3.8.18/x64/lib/python3.8/site-packages/applitools/core_universal/bin/core/__sea/dist/open-eyes.js:94:22)</status>
</kw>
<status status="FAIL" start="2024-02-29T14:42:48.103219" elapsed="12.666070">EyesLibraryError: Failed to run EyesLibrary
Traceback (most recent call last):
  File "/opt/hostedtoolcache/Python/3.8.18/x64/lib/python3.8/site-packages/EyesLibrary/__init__.py", line 266, in run_keyword
    return DynamicCore.run_keyword(self, name, args, kwargs)
  File "/opt/hostedtoolcache/Python/3.8.18/x64/lib/python3.8/site-packages/robotlibcore.py", line 133, in run_keyword
    return self.keywords[name](*args, **(kwargs or {}))
  File "/opt/hostedtoolcache/Python/3.8.18/x64/lib/python3.8/site-packages/EyesLibrary/keywords/session.py", line 145, in open
    return eyes.open(self.fetch_driver())
  File "/opt/hostedtoolcache/Python/3.8.18/x64/lib/python3.8/site-packages/applitools/common/eyes.py", line 291, in open
    self._open(app_name, test_name, viewport_size, driver)
  File "/opt/hostedtoolcache/Python/3.8.18/x64/lib/python3.8/site-packages/applitools/common/eyes.py", line 220, in _open
    self._eyes_ref = self._commands.manager_open_eyes(
  File "/opt/hostedtoolcache/Python/3.8.18/x64/lib/python3.8/site-packages/applitools/common/command_executor.py", line 156, in manager_open_eyes
    return self._checked_command(context, "EyesManager.openEyes", payload)
    [ Message content over the limit has been removed. ]
    at async req2 (/opt/hostedtoolcache/Python/3.8.18/x64/lib/python3.8/site-packages/applitools/core_universal/bin/core/__sea/node_modules/@applitools/req/dist/index.cjs:9729:18)
    at async req (/opt/hostedtoolcache/Python/3.8.18/x64/lib/python3.8/site-packages/applitools/core_universal/bin/core/__sea/node_modules/@applitools/req/dist/index.cjs:9640:12)
    at async getAccountInfo (/opt/hostedtoolcache/Python/3.8.18/x64/lib/python3.8/site-packages/applitools/core_universal/bin/core/__sea/node_modules/@applitools/core-base/dist/server/requests.js:310:26)
    at async Object.getAccountInfo (/opt/hostedtoolcache/Python/3.8.18/x64/lib/python3.8/site-packages/applitools/core_universal/bin/core/__sea/node_modules/@applitools/core-base/dist/get-account-info.js:34:25)
    at async Object.openEyes (/opt/hostedtoolcache/Python/3.8.18/x64/lib/python3.8/site-packages/applitools/core_universal/bin/core/__sea/dist/ufg/open-eyes.js:55:25)
    at async getTypedEyes (/opt/hostedtoolcache/Python/3.8.18/x64/lib/python3.8/site-packages/applitools/core_universal/bin/core/__sea/dist/get-typed-eyes.js:9:20)
    at async openEyes (/opt/hostedtoolcache/Python/3.8.18/x64/lib/python3.8/site-packages/applitools/core_universal/bin/core/__sea/dist/open-eyes.js:94:22)</status>
</kw>
<kw name="After Visual Tests" owner="common_keywords" type="TEARDOWN">
<kw name="Close All Browsers" owner="SeleniumLibrary">
<doc>Closes all open browsers and resets the browser cache.</doc>
<status status="PASS" start="2024-02-29T14:43:00.775241" elapsed="0.062916"/>
</kw>
<status status="PASS" start="2024-02-29T14:43:00.774400" elapsed="0.064018"/>
</kw>
<status status="FAIL" start="2024-02-29T14:42:48.101854" elapsed="12.736718">Setup failed:
EyesLibraryError: Failed to run EyesLibrary
Traceback (most recent call last):
  File "/opt/hostedtoolcache/Python/3.8.18/x64/lib/python3.8/site-packages/EyesLibrary/__init__.py", line 266, in run_keyword
    return DynamicCore.run_keyword(self, name, args, kwargs)
  File "/opt/hostedtoolcache/Python/3.8.18/x64/lib/python3.8/site-packages/robotlibcore.py", line 133, in run_keyword
    return self.keywords[name](*args, **(kwargs or {}))
  File "/opt/hostedtoolcache/Python/3.8.18/x64/lib/python3.8/site-packages/EyesLibrary/keywords/session.py", line 145, in open
    return eyes.open(self.fetch_driver())
  File "/opt/hostedtoolcache/Python/3.8.18/x64/lib/python3.8/site-packages/applitools/common/eyes.py", line 291, in open
    self._open(app_name, test_name, viewport_size, driver)
  File "/opt/hostedtoolcache/Python/3.8.18/x64/lib/python3.8/site-packages/applitools/common/eyes.py", line 220, in _open
    self._eyes_ref = self._commands.manager_open_eyes(
  File "/opt/hostedtoolcache/Python/3.8.18/x64/lib/python3.8/site-packages/applitools/common/command_executor.py", line 156, in manager_open_eyes
    return self._checked_command(context, "EyesManager.openEyes", payload)
    [ Message content over the limit has been removed. ]
    at async req2 (/opt/hostedtoolcache/Python/3.8.18/x64/lib/python3.8/site-packages/applitools/core_universal/bin/core/__sea/node_modules/@applitools/req/dist/index.cjs:9729:18)
    at async req (/opt/hostedtoolcache/Python/3.8.18/x64/lib/python3.8/site-packages/applitools/core_universal/bin/core/__sea/node_modules/@applitools/req/dist/index.cjs:9640:12)
    at async getAccountInfo (/opt/hostedtoolcache/Python/3.8.18/x64/lib/python3.8/site-packages/applitools/core_universal/bin/core/__sea/node_modules/@applitools/core-base/dist/server/requests.js:310:26)
    at async Object.getAccountInfo (/opt/hostedtoolcache/Python/3.8.18/x64/lib/python3.8/site-packages/applitools/core_universal/bin/core/__sea/node_modules/@applitools/core-base/dist/get-account-info.js:34:25)
    at async Object.openEyes (/opt/hostedtoolcache/Python/3.8.18/x64/lib/python3.8/site-packages/applitools/core_universal/bin/core/__sea/dist/ufg/open-eyes.js:55:25)
    at async getTypedEyes (/opt/hostedtoolcache/Python/3.8.18/x64/lib/python3.8/site-packages/applitools/core_universal/bin/core/__sea/dist/get-typed-eyes.js:9:20)
    at async openEyes (/opt/hostedtoolcache/Python/3.8.18/x64/lib/python3.8/site-packages/applitools/core_universal/bin/core/__sea/dist/open-eyes.js:94:22)</status>
</test>
<meta name="Applitools TestResults Path">/tmp/tmpfrtw5ze7/EyesTestResults-cc261ff095c34a9bbd951460ed85b36c.json</meta>
<status status="FAIL" start="2024-02-29T14:42:46.417003" elapsed="14.422612"/>
</suite>
<doc>[https://pabot.org/?ref=log|Pabot] result from 3 executions.</doc>
<status status="FAIL" start="2024-02-29T14:42:46.400000" elapsed="14.354743"/>
</suite>
<statistics>
<total>
<stat pass="0" fail="3" skip="0">All Tests</stat>
</total>
<tag>
</tag>
<suite>
<stat pass="0" fail="3" skip="0" id="s1" name="Tests">Tests</stat>
<stat pass="0" fail="1" skip="0" id="s1-s1" name="Visual Test 1">Tests.Visual Test 1</stat>
<stat pass="0" fail="1" skip="0" id="s1-s2" name="Visual Test 2">Tests.Visual Test 2</stat>
<stat pass="0" fail="1" skip="0" id="s1-s3" name="Visual Test 3">Tests.Visual Test 3</stat>
</suite>
</statistics>
<errors>
<msg time="2024-02-29T14:43:00.766754" level="ERROR">Re-raising an error received from SDK server: USDKFailure('Request "getAccountInfo" [0--20edbb2b-5a2f-4b88-b5bb-de5781c2a650] that was sent to the address "[GET]https://eyesapi.applitools.com/api/sessions/renderinfo?apiKey=%3Capi-key%3E" failed due to unexpected status Unauthorized(401)', '    at Object.afterResponse (/opt/hostedtoolcache/Python/3.8.18/x64/lib/python3.8/site-packages/applitools/core_universal/bin/core/__sea/node_modules/@applitools/core-base/dist/server/req-eyes.js:101:23)\n    at /opt/hostedtoolcache/Python/3.8.18/x64/lib/python3.8/site-packages/applitools/core_universal/bin/core/__sea/node_modules/@applitools/req/dist/index.cjs:9828:97\n    at process.processTicksAndRejections (node:internal/process/task_queues:95:5)\n    at async req2 (/opt/hostedtoolcache/Python/3.8.18/x64/lib/python3.8/site-packages/applitools/core_universal/bin/core/__sea/node_modules/@applitools/req/dist/index.cjs:9729:18)\n    at async req (/opt/hostedtoolcache/Python/3.8.18/x64/lib/python3.8/site-packages/applitools/core_universal/bin/core/__sea/node_modules/@applitools/req/dist/index.cjs:9640:12)\n    at async getAccountInfo (/opt/hostedtoolcache/Python/3.8.18/x64/lib/python3.8/site-packages/applitools/core_universal/bin/core/__sea/node_modules/@applitools/core-base/dist/server/requests.js:310:26)\n    at async Object.getAccountInfo (/opt/hostedtoolcache/Python/3.8.18/x64/lib/python3.8/site-packages/applitools/core_universal/bin/core/__sea/node_modules/@applitools/core-base/dist/get-account-info.js:34:25)\n    at async Object.openEyes (/opt/hostedtoolcache/Python/3.8.18/x64/lib/python3.8/site-packages/applitools/core_universal/bin/core/__sea/dist/ufg/open-eyes.js:55:25)\n    at async getTypedEyes (/opt/hostedtoolcache/Python/3.8.18/x64/lib/python3.8/site-packages/applitools/core_universal/bin/core/__sea/dist/get-typed-eyes.js:9:20)\n    at async openEyes (/opt/hostedtoolcache/Python/3.8.18/x64/lib/python3.8/site-packages/applitools/core_universal/bin/core/__sea/dist/open-eyes.js:94:22)')</msg>
<msg time="2024-02-29T14:43:00.484399" level="ERROR">Re-raising an error received from SDK server: USDKFailure('Request "getAccountInfo" [0--df7a502b-23e7-4a26-a258-b38207ca22d6] that was sent to the address "[GET]https://eyesapi.applitools.com/api/sessions/renderinfo?apiKey=%3Capi-key%3E" failed due to unexpected status Unauthorized(401)', '    at Object.afterResponse (/opt/hostedtoolcache/Python/3.8.18/x64/lib/python3.8/site-packages/applitools/core_universal/bin/core/__sea/node_modules/@applitools/core-base/dist/server/req-eyes.js:101:23)\n    at /opt/hostedtoolcache/Python/3.8.18/x64/lib/python3.8/site-packages/applitools/core_universal/bin/core/__sea/node_modules/@applitools/req/dist/index.cjs:9828:97\n    at process.processTicksAndRejections (node:internal/process/task_queues:95:5)\n    at async req2 (/opt/hostedtoolcache/Python/3.8.18/x64/lib/python3.8/site-packages/applitools/core_universal/bin/core/__sea/node_modules/@applitools/req/dist/index.cjs:9729:18)\n    at async req (/opt/hostedtoolcache/Python/3.8.18/x64/lib/python3.8/site-packages/applitools/core_universal/bin/core/__sea/node_modules/@applitools/req/dist/index.cjs:9640:12)\n    at async getAccountInfo (/opt/hostedtoolcache/Python/3.8.18/x64/lib/python3.8/site-packages/applitools/core_universal/bin/core/__sea/node_modules/@applitools/core-base/dist/server/requests.js:310:26)\n    at async Object.getAccountInfo (/opt/hostedtoolcache/Python/3.8.18/x64/lib/python3.8/site-packages/applitools/core_universal/bin/core/__sea/node_modules/@applitools/core-base/dist/get-account-info.js:34:25)\n    at async Object.openEyes (/opt/hostedtoolcache/Python/3.8.18/x64/lib/python3.8/site-packages/applitools/core_universal/bin/core/__sea/dist/ufg/open-eyes.js:55:25)\n    at async getTypedEyes (/opt/hostedtoolcache/Python/3.8.18/x64/lib/python3.8/site-packages/applitools/core_universal/bin/core/__sea/dist/get-typed-eyes.js:9:20)\n    at async openEyes (/opt/hostedtoolcache/Python/3.8.18/x64/lib/python3.8/site-packages/applitools/core_universal/bin/core/__sea/dist/open-eyes.js:94:22)')</msg>
<msg time="2024-02-29T14:43:00.765575" level="ERROR">Re-raising an error received from SDK server: USDKFailure('Request "getAccountInfo" [0--f9ae0e72-c1ab-4601-88c4-ad9cf2b4f1bc] that was sent to the address "[GET]https://eyesapi.applitools.com/api/sessions/renderinfo?apiKey=%3Capi-key%3E" failed due to unexpected status Unauthorized(401)', '    at Object.afterResponse (/opt/hostedtoolcache/Python/3.8.18/x64/lib/python3.8/site-packages/applitools/core_universal/bin/core/__sea/node_modules/@applitools/core-base/dist/server/req-eyes.js:101:23)\n    at /opt/hostedtoolcache/Python/3.8.18/x64/lib/python3.8/site-packages/applitools/core_universal/bin/core/__sea/node_modules/@applitools/req/dist/index.cjs:9828:97\n    at process.processTicksAndRejections (node:internal/process/task_queues:95:5)\n    at async req2 (/opt/hostedtoolcache/Python/3.8.18/x64/lib/python3.8/site-packages/applitools/core_universal/bin/core/__sea/node_modules/@applitools/req/dist/index.cjs:9729:18)\n    at async req (/opt/hostedtoolcache/Python/3.8.18/x64/lib/python3.8/site-packages/applitools/core_universal/bin/core/__sea/node_modules/@applitools/req/dist/index.cjs:9640:12)\n    at async getAccountInfo (/opt/hostedtoolcache/Python/3.8.18/x64/lib/python3.8/site-packages/applitools/core_universal/bin/core/__sea/node_modules/@applitools/core-base/dist/server/requests.js:310:26)\n    at async Object.getAccountInfo (/opt/hostedtoolcache/Python/3.8.18/x64/lib/python3.8/site-packages/applitools/core_universal/bin/core/__sea/node_modules/@applitools/core-base/dist/get-account-info.js:34:25)\n    at async Object.openEyes (/opt/hostedtoolcache/Python/3.8.18/x64/lib/python3.8/site-packages/applitools/core_universal/bin/core/__sea/dist/ufg/open-eyes.js:55:25)\n    at async getTypedEyes (/opt/hostedtoolcache/Python/3.8.18/x64/lib/python3.8/site-packages/applitools/core_universal/bin/core/__sea/dist/get-typed-eyes.js:9:20)\n    at async openEyes (/opt/hostedtoolcache/Python/3.8.18/x64/lib/python3.8/site-packages/applitools/core_universal/bin/core/__sea/dist/open-eyes.js:94:22)')</msg>
</errors>
</robot>
