<?xml version="1.0" encoding="UTF-8"?>
<robot generator="Robot 7.0 (Python 3.8.18 on linux)" generated="2024-04-24T18:23:12.040931" rpa="false" schemaversion="5">
<suite id="s1" name="Tests" source="/home/runner/work/robot-applitools-tests/robot-applitools-tests/tests">
<suite id="s1-s1" name="Visual Test 1" source="/home/runner/work/robot-applitools-tests/robot-applitools-tests/tests/visual_test_1.robot">
<test id="s1-s1-t1" name="Why Applitools Page" line="10">
<kw name="Before Visual Tests" owner="common_keywords" type="SETUP">
<kw name="Open Browser" owner="SeleniumLibrary">
<msg time="2024-04-24T18:23:13.710426" level="INFO">Opening browser 'headless Chrome' to base url 'https://applitools.com/'.</msg>
<arg>${BASE_URL}</arg>
<arg>${HEADLESS} ${BROWSER}</arg>
<doc>Opens a new browser instance to the optional ``url``.</doc>
<status status="PASS" start="2024-04-24T18:23:13.709920" elapsed="24.337890"/>
</kw>
<kw name="Eyes Open" owner="EyesLibrary">
<msg time="2024-04-24T18:23:38.627714" level="ERROR">Re-raising an error received from SDK server: USDKFailure('Request "getAccountInfo" [0--8d77ad0b-6bfc-4f1f-9b13-1e7ff2deb91d] that was sent to the address "[GET]https://eyesapi.applitools.com/api/sessions/renderinfo?apiKey=%3Capi-key%3E" failed due to unexpected status Unauthorized(401)', '    at Object.afterResponse (/opt/hostedtoolcache/Python/3.8.18/x64/lib/python3.8/site-packages/applitools/core_universal/bin/core/__sea/node_modules/@applitools/core-base/dist/server/req-eyes.js:103:23)\n    at process.processTicksAndRejections (node:internal/process/task_queues:95:5)\n    at async /opt/hostedtoolcache/Python/3.8.18/x64/lib/python3.8/site-packages/applitools/core_universal/bin/core/__sea/node_modules/@applitools/req/dist/index.cjs:9828:20\n    at async req2 (/opt/hostedtoolcache/Python/3.8.18/x64/lib/python3.8/site-packages/applitools/core_universal/bin/core/__sea/node_modules/@applitools/req/dist/index.cjs:9729:18)\n    at async req (/opt/hostedtoolcache/Python/3.8.18/x64/lib/python3.8/site-packages/applitools/core_universal/bin/core/__sea/node_modules/@applitools/req/dist/index.cjs:9640:12)\n    at async getAccountInfo (/opt/hostedtoolcache/Python/3.8.18/x64/lib/python3.8/site-packages/applitools/core_universal/bin/core/__sea/node_modules/@applitools/core-base/dist/server/requests.js:324:26)\n    at async Object.getAccountInfo (/opt/hostedtoolcache/Python/3.8.18/x64/lib/python3.8/site-packages/applitools/core_universal/bin/core/__sea/node_modules/@applitools/core-base/dist/get-account-info.js:34:25)\n    at async Object.openEyes (/opt/hostedtoolcache/Python/3.8.18/x64/lib/python3.8/site-packages/applitools/core_universal/bin/core/__sea/dist/ufg/open-eyes.js:56:25)\n    at async getTypedEyes (/opt/hostedtoolcache/Python/3.8.18/x64/lib/python3.8/site-packages/applitools/core_universal/bin/core/__sea/dist/get-typed-eyes.js:9:20)\n    at async openEyes (/opt/hostedtoolcache/Python/3.8.18/x64/lib/python3.8/site-packages/applitools/core_universal/bin/core/__sea/dist/open-eyes.js:96:22)')</msg>
<msg time="2024-04-24T18:23:38.628923" level="FAIL">EyesLibraryError: Failed to run EyesLibrary
Traceback (most recent call last):
  File "/opt/hostedtoolcache/Python/3.8.18/x64/lib/python3.8/site-packages/EyesLibrary/__init__.py", line 266, in run_keyword
    return DynamicCore.run_keyword(self, name, args, kwargs)
  File "/opt/hostedtoolcache/Python/3.8.18/x64/lib/python3.8/site-packages/robotlibcore.py", line 173, in run_keyword
    return self.keywords[name](*args, **(kwargs or {}))
  File "/opt/hostedtoolcache/Python/3.8.18/x64/lib/python3.8/site-packages/EyesLibrary/keywords/session.py", line 145, in open
    return eyes.open(self.fetch_driver())
  File "/opt/hostedtoolcache/Python/3.8.18/x64/lib/python3.8/site-packages/applitools/common/eyes.py", line 291, in open
    self._open(app_name, test_name, viewport_size, driver)
  File "/opt/hostedtoolcache/Python/3.8.18/x64/lib/python3.8/site-packages/applitools/common/eyes.py", line 220, in _open
    self._eyes_ref = self._commands.manager_open_eyes(
  File "/opt/hostedtoolcache/Python/3.8.18/x64/lib/python3.8/site-packages/applitools/common/command_executor.py", line 156, in manager_open_eyes
    return self._checked_command(context, "EyesManager.openEyes", payload)
  File "/opt/hostedtoolcache/Python/3.8.18/x64/lib/python3.8/site-packages/applitools/common/command_executor.py", line 284, in _checked_command
    _check_error(response_payload)
  File "/opt/hostedtoolcache/Python/3.8.18/x64/lib/python3.8/site-packages/applitools/common/command_executor.py", line 294, in _check_error
    raise usdk_error
applitools.common.errors.USDKFailure: Request "getAccountInfo" [0--8d77ad0b-6bfc-4f1f-9b13-1e7ff2deb91d] that was sent to the address "[GET]https://eyesapi.applitools.com/api/sessions/renderinfo?apiKey=%3Capi-key%3E" failed due to unexpected status Unauthorized(401)
    at Object.afterResponse (/opt/hostedtoolcache/Python/3.8.18/x64/lib/python3.8/site-packages/applitools/core_universal/bin/core/__sea/node_modules/@applitools/core-base/dist/server/req-eyes.js:103:23)
    at process.processTicksAndRejections (node:internal/process/task_queues:95:5)
    at async /opt/hostedtoolcache/Python/3.8.18/x64/lib/python3.8/site-packages/applitools/core_universal/bin/core/__sea/node_modules/@applitools/req/dist/index.cjs:9828:20
    at async req2 (/opt/hostedtoolcache/Python/3.8.18/x64/lib/python3.8/site-packages/applitools/core_universal/bin/core/__sea/node_modules/@applitools/req/dist/index.cjs:9729:18)
    at async req (/opt/hostedtoolcache/Python/3.8.18/x64/lib/python3.8/site-packages/applitools/core_universal/bin/core/__sea/node_modules/@applitools/req/dist/index.cjs:9640:12)
    at async getAccountInfo (/opt/hostedtoolcache/Python/3.8.18/x64/lib/python3.8/site-packages/applitools/core_universal/bin/core/__sea/node_modules/@applitools/core-base/dist/server/requests.js:324:26)
    at async Object.getAccountInfo (/opt/hostedtoolcache/Python/3.8.18/x64/lib/python3.8/site-packages/applitools/core_universal/bin/core/__sea/node_modules/@applitools/core-base/dist/get-account-info.js:34:25)
    at async Object.openEyes (/opt/hostedtoolcache/Python/3.8.18/x64/lib/python3.8/site-packages/applitools/core_universal/bin/core/__sea/dist/ufg/open-eyes.js:56:25)
    at async getTypedEyes (/opt/hostedtoolcache/Python/3.8.18/x64/lib/python3.8/site-packages/applitools/core_universal/bin/core/__sea/dist/get-typed-eyes.js:9:20)
    at async openEyes (/opt/hostedtoolcache/Python/3.8.18/x64/lib/python3.8/site-packages/applitools/core_universal/bin/core/__sea/dist/open-eyes.js:96:22)
</msg>
<arg>${TEST_NAME}</arg>
<arg>${VIEWPORT_SIZE}</arg>
<arg>${APP_NAME}</arg>
<arg>${HOST_OS}</arg>
<arg>${HOST_APP}</arg>
<arg>${MATCH_LEVEL}</arg>
<arg>${BASELINE_ENV_NAME}</arg>
<arg>${BATCH_NAME}</arg>
<tag>Check flow</tag>
<doc>Shared parameters section from `applitools.yaml` could be overwritten during `Eyes Open` call, see `Preconditions`.</doc>
<status status="FAIL" start="2024-04-24T18:23:38.048602" elapsed="0.580598">EyesLibraryError: Failed to run EyesLibrary
Traceback (most recent call last):
  File "/opt/hostedtoolcache/Python/3.8.18/x64/lib/python3.8/site-packages/EyesLibrary/__init__.py", line 266, in run_keyword
    return DynamicCore.run_keyword(self, name, args, kwargs)
  File "/opt/hostedtoolcache/Python/3.8.18/x64/lib/python3.8/site-packages/robotlibcore.py", line 173, in run_keyword
    return self.keywords[name](*args, **(kwargs or {}))
  File "/opt/hostedtoolcache/Python/3.8.18/x64/lib/python3.8/site-packages/EyesLibrary/keywords/session.py", line 145, in open
    return eyes.open(self.fetch_driver())
  File "/opt/hostedtoolcache/Python/3.8.18/x64/lib/python3.8/site-packages/applitools/common/eyes.py", line 291, in open
    self._open(app_name, test_name, viewport_size, driver)
  File "/opt/hostedtoolcache/Python/3.8.18/x64/lib/python3.8/site-packages/applitools/common/eyes.py", line 220, in _open
    self._eyes_ref = self._commands.manager_open_eyes(
  File "/opt/hostedtoolcache/Python/3.8.18/x64/lib/python3.8/site-packages/applitools/common/command_executor.py", line 156, in manager_open_eyes
    return self._checked_command(context, "EyesManager.openEyes", payload)
    [ Message content over the limit has been removed. ]
    at async req2 (/opt/hostedtoolcache/Python/3.8.18/x64/lib/python3.8/site-packages/applitools/core_universal/bin/core/__sea/node_modules/@applitools/req/dist/index.cjs:9729:18)
    at async req (/opt/hostedtoolcache/Python/3.8.18/x64/lib/python3.8/site-packages/applitools/core_universal/bin/core/__sea/node_modules/@applitools/req/dist/index.cjs:9640:12)
    at async getAccountInfo (/opt/hostedtoolcache/Python/3.8.18/x64/lib/python3.8/site-packages/applitools/core_universal/bin/core/__sea/node_modules/@applitools/core-base/dist/server/requests.js:324:26)
    at async Object.getAccountInfo (/opt/hostedtoolcache/Python/3.8.18/x64/lib/python3.8/site-packages/applitools/core_universal/bin/core/__sea/node_modules/@applitools/core-base/dist/get-account-info.js:34:25)
    at async Object.openEyes (/opt/hostedtoolcache/Python/3.8.18/x64/lib/python3.8/site-packages/applitools/core_universal/bin/core/__sea/dist/ufg/open-eyes.js:56:25)
    at async getTypedEyes (/opt/hostedtoolcache/Python/3.8.18/x64/lib/python3.8/site-packages/applitools/core_universal/bin/core/__sea/dist/get-typed-eyes.js:9:20)
    at async openEyes (/opt/hostedtoolcache/Python/3.8.18/x64/lib/python3.8/site-packages/applitools/core_universal/bin/core/__sea/dist/open-eyes.js:96:22)</status>
</kw>
<status status="FAIL" start="2024-04-24T18:23:13.708638" elapsed="24.921295">EyesLibraryError: Failed to run EyesLibrary
Traceback (most recent call last):
  File "/opt/hostedtoolcache/Python/3.8.18/x64/lib/python3.8/site-packages/EyesLibrary/__init__.py", line 266, in run_keyword
    return DynamicCore.run_keyword(self, name, args, kwargs)
  File "/opt/hostedtoolcache/Python/3.8.18/x64/lib/python3.8/site-packages/robotlibcore.py", line 173, in run_keyword
    return self.keywords[name](*args, **(kwargs or {}))
  File "/opt/hostedtoolcache/Python/3.8.18/x64/lib/python3.8/site-packages/EyesLibrary/keywords/session.py", line 145, in open
    return eyes.open(self.fetch_driver())
  File "/opt/hostedtoolcache/Python/3.8.18/x64/lib/python3.8/site-packages/applitools/common/eyes.py", line 291, in open
    self._open(app_name, test_name, viewport_size, driver)
  File "/opt/hostedtoolcache/Python/3.8.18/x64/lib/python3.8/site-packages/applitools/common/eyes.py", line 220, in _open
    self._eyes_ref = self._commands.manager_open_eyes(
  File "/opt/hostedtoolcache/Python/3.8.18/x64/lib/python3.8/site-packages/applitools/common/command_executor.py", line 156, in manager_open_eyes
    return self._checked_command(context, "EyesManager.openEyes", payload)
    [ Message content over the limit has been removed. ]
    at async req2 (/opt/hostedtoolcache/Python/3.8.18/x64/lib/python3.8/site-packages/applitools/core_universal/bin/core/__sea/node_modules/@applitools/req/dist/index.cjs:9729:18)
    at async req (/opt/hostedtoolcache/Python/3.8.18/x64/lib/python3.8/site-packages/applitools/core_universal/bin/core/__sea/node_modules/@applitools/req/dist/index.cjs:9640:12)
    at async getAccountInfo (/opt/hostedtoolcache/Python/3.8.18/x64/lib/python3.8/site-packages/applitools/core_universal/bin/core/__sea/node_modules/@applitools/core-base/dist/server/requests.js:324:26)
    at async Object.getAccountInfo (/opt/hostedtoolcache/Python/3.8.18/x64/lib/python3.8/site-packages/applitools/core_universal/bin/core/__sea/node_modules/@applitools/core-base/dist/get-account-info.js:34:25)
    at async Object.openEyes (/opt/hostedtoolcache/Python/3.8.18/x64/lib/python3.8/site-packages/applitools/core_universal/bin/core/__sea/dist/ufg/open-eyes.js:56:25)
    at async getTypedEyes (/opt/hostedtoolcache/Python/3.8.18/x64/lib/python3.8/site-packages/applitools/core_universal/bin/core/__sea/dist/get-typed-eyes.js:9:20)
    at async openEyes (/opt/hostedtoolcache/Python/3.8.18/x64/lib/python3.8/site-packages/applitools/core_universal/bin/core/__sea/dist/open-eyes.js:96:22)</status>
</kw>
<kw name="After Visual Tests" owner="common_keywords" type="TEARDOWN">
<kw name="Close All Browsers" owner="SeleniumLibrary">
<doc>Closes all open browsers and resets the browser cache.</doc>
<status status="PASS" start="2024-04-24T18:23:38.630955" elapsed="0.065686"/>
</kw>
<status status="PASS" start="2024-04-24T18:23:38.630467" elapsed="0.066411"/>
</kw>
<status status="FAIL" start="2024-04-24T18:23:13.707215" elapsed="24.989774">Setup failed:
EyesLibraryError: Failed to run EyesLibrary
Traceback (most recent call last):
  File "/opt/hostedtoolcache/Python/3.8.18/x64/lib/python3.8/site-packages/EyesLibrary/__init__.py", line 266, in run_keyword
    return DynamicCore.run_keyword(self, name, args, kwargs)
  File "/opt/hostedtoolcache/Python/3.8.18/x64/lib/python3.8/site-packages/robotlibcore.py", line 173, in run_keyword
    return self.keywords[name](*args, **(kwargs or {}))
  File "/opt/hostedtoolcache/Python/3.8.18/x64/lib/python3.8/site-packages/EyesLibrary/keywords/session.py", line 145, in open
    return eyes.open(self.fetch_driver())
  File "/opt/hostedtoolcache/Python/3.8.18/x64/lib/python3.8/site-packages/applitools/common/eyes.py", line 291, in open
    self._open(app_name, test_name, viewport_size, driver)
  File "/opt/hostedtoolcache/Python/3.8.18/x64/lib/python3.8/site-packages/applitools/common/eyes.py", line 220, in _open
    self._eyes_ref = self._commands.manager_open_eyes(
  File "/opt/hostedtoolcache/Python/3.8.18/x64/lib/python3.8/site-packages/applitools/common/command_executor.py", line 156, in manager_open_eyes
    return self._checked_command(context, "EyesManager.openEyes", payload)
    [ Message content over the limit has been removed. ]
    at async req2 (/opt/hostedtoolcache/Python/3.8.18/x64/lib/python3.8/site-packages/applitools/core_universal/bin/core/__sea/node_modules/@applitools/req/dist/index.cjs:9729:18)
    at async req (/opt/hostedtoolcache/Python/3.8.18/x64/lib/python3.8/site-packages/applitools/core_universal/bin/core/__sea/node_modules/@applitools/req/dist/index.cjs:9640:12)
    at async getAccountInfo (/opt/hostedtoolcache/Python/3.8.18/x64/lib/python3.8/site-packages/applitools/core_universal/bin/core/__sea/node_modules/@applitools/core-base/dist/server/requests.js:324:26)
    at async Object.getAccountInfo (/opt/hostedtoolcache/Python/3.8.18/x64/lib/python3.8/site-packages/applitools/core_universal/bin/core/__sea/node_modules/@applitools/core-base/dist/get-account-info.js:34:25)
    at async Object.openEyes (/opt/hostedtoolcache/Python/3.8.18/x64/lib/python3.8/site-packages/applitools/core_universal/bin/core/__sea/dist/ufg/open-eyes.js:56:25)
    at async getTypedEyes (/opt/hostedtoolcache/Python/3.8.18/x64/lib/python3.8/site-packages/applitools/core_universal/bin/core/__sea/dist/get-typed-eyes.js:9:20)
    at async openEyes (/opt/hostedtoolcache/Python/3.8.18/x64/lib/python3.8/site-packages/applitools/core_universal/bin/core/__sea/dist/open-eyes.js:96:22)</status>
</test>
<meta name="Applitools TestResults Path">/tmp/tmpatk3h_l2/EyesTestResults-9b74ce0b298c435189af887974d120fe.json</meta>
<status status="FAIL" start="2024-04-24T18:23:12.063165" elapsed="26.634569"/>
</suite>
<status status="FAIL" start="2024-04-24T18:23:12.046182" elapsed="26.652320"/>
</suite>
<statistics>
<total>
<stat pass="0" fail="1" skip="0">All Tests</stat>
</total>
<tag>
</tag>
<suite>
<stat pass="0" fail="1" skip="0" id="s1" name="Tests">Tests</stat>
<stat pass="0" fail="1" skip="0" id="s1-s1" name="Visual Test 1">Tests.Visual Test 1</stat>
</suite>
</statistics>
<errors>
<msg time="2024-04-24T18:23:38.627714" level="ERROR">Re-raising an error received from SDK server: USDKFailure('Request "getAccountInfo" [0--8d77ad0b-6bfc-4f1f-9b13-1e7ff2deb91d] that was sent to the address "[GET]https://eyesapi.applitools.com/api/sessions/renderinfo?apiKey=%3Capi-key%3E" failed due to unexpected status Unauthorized(401)', '    at Object.afterResponse (/opt/hostedtoolcache/Python/3.8.18/x64/lib/python3.8/site-packages/applitools/core_universal/bin/core/__sea/node_modules/@applitools/core-base/dist/server/req-eyes.js:103:23)\n    at process.processTicksAndRejections (node:internal/process/task_queues:95:5)\n    at async /opt/hostedtoolcache/Python/3.8.18/x64/lib/python3.8/site-packages/applitools/core_universal/bin/core/__sea/node_modules/@applitools/req/dist/index.cjs:9828:20\n    at async req2 (/opt/hostedtoolcache/Python/3.8.18/x64/lib/python3.8/site-packages/applitools/core_universal/bin/core/__sea/node_modules/@applitools/req/dist/index.cjs:9729:18)\n    at async req (/opt/hostedtoolcache/Python/3.8.18/x64/lib/python3.8/site-packages/applitools/core_universal/bin/core/__sea/node_modules/@applitools/req/dist/index.cjs:9640:12)\n    at async getAccountInfo (/opt/hostedtoolcache/Python/3.8.18/x64/lib/python3.8/site-packages/applitools/core_universal/bin/core/__sea/node_modules/@applitools/core-base/dist/server/requests.js:324:26)\n    at async Object.getAccountInfo (/opt/hostedtoolcache/Python/3.8.18/x64/lib/python3.8/site-packages/applitools/core_universal/bin/core/__sea/node_modules/@applitools/core-base/dist/get-account-info.js:34:25)\n    at async Object.openEyes (/opt/hostedtoolcache/Python/3.8.18/x64/lib/python3.8/site-packages/applitools/core_universal/bin/core/__sea/dist/ufg/open-eyes.js:56:25)\n    at async getTypedEyes (/opt/hostedtoolcache/Python/3.8.18/x64/lib/python3.8/site-packages/applitools/core_universal/bin/core/__sea/dist/get-typed-eyes.js:9:20)\n    at async openEyes (/opt/hostedtoolcache/Python/3.8.18/x64/lib/python3.8/site-packages/applitools/core_universal/bin/core/__sea/dist/open-eyes.js:96:22)')</msg>
</errors>
</robot>
